{
 "cells": [
  {
   "cell_type": "markdown",
   "metadata": {},
   "source": [
    "# Import"
   ]
  },
  {
   "cell_type": "code",
   "execution_count": 1,
   "metadata": {},
   "outputs": [
    {
     "name": "stderr",
     "output_type": "stream",
     "text": [
      "2024-11-27 18:04:16.862570: I tensorflow/core/util/port.cc:153] oneDNN custom operations are on. You may see slightly different numerical results due to floating-point round-off errors from different computation orders. To turn them off, set the environment variable `TF_ENABLE_ONEDNN_OPTS=0`.\n",
      "2024-11-27 18:04:16.871431: E external/local_xla/xla/stream_executor/cuda/cuda_fft.cc:477] Unable to register cuFFT factory: Attempting to register factory for plugin cuFFT when one has already been registered\n",
      "WARNING: All log messages before absl::InitializeLog() is called are written to STDERR\n",
      "E0000 00:00:1732727056.882373   82932 cuda_dnn.cc:8310] Unable to register cuDNN factory: Attempting to register factory for plugin cuDNN when one has already been registered\n",
      "E0000 00:00:1732727056.885616   82932 cuda_blas.cc:1418] Unable to register cuBLAS factory: Attempting to register factory for plugin cuBLAS when one has already been registered\n",
      "2024-11-27 18:04:16.896716: I tensorflow/core/platform/cpu_feature_guard.cc:210] This TensorFlow binary is optimized to use available CPU instructions in performance-critical operations.\n",
      "To enable the following instructions: AVX2 AVX_VNNI FMA, in other operations, rebuild TensorFlow with the appropriate compiler flags.\n"
     ]
    }
   ],
   "source": [
    "from deepface import DeepFace\n",
    "import os\n",
    "from PIL import Image\n",
    "import shutil\n",
    "import cv2"
   ]
  },
  {
   "cell_type": "code",
   "execution_count": 2,
   "metadata": {},
   "outputs": [],
   "source": [
    "# Dossiers source et destination\n",
    "source_dir = 'data'  \n",
    "dest_dir = 'data_face'"
   ]
  },
  {
   "cell_type": "code",
   "execution_count": 3,
   "metadata": {},
   "outputs": [],
   "source": [
    "if not os.path.exists(dest_dir):\n",
    "    os.makedirs(dest_dir)"
   ]
  },
  {
   "cell_type": "code",
   "execution_count": 4,
   "metadata": {},
   "outputs": [],
   "source": [
    "# Fonction pour redimensionner les images\n",
    "def resize_image(image_path, scale_percent):\n",
    "\n",
    "    img = cv2.imread(image_path)\n",
    "    img = cv2.cvtColor(img, cv2.COLOR_BGR2RGB)\n",
    "\n",
    "    width = int(img.shape[1] * scale_percent / 100)\n",
    "    height = int(img.shape[0] * scale_percent / 100)\n",
    "    dim = (width, height)\n",
    "\n",
    "    img_resize = cv2.resize(img, dim, interpolation=cv2.INTER_AREA)\n",
    "\n",
    "    img_resize = cv2.cvtColor(img_resize, cv2.COLOR_BGR2RGB)\n",
    "\n",
    "    return img_resize"
   ]
  },
  {
   "cell_type": "code",
   "execution_count": 5,
   "metadata": {},
   "outputs": [],
   "source": [
    "# Fonction pour extraire les visages avec DeepFace\n",
    "def extract_faces(img, image_path, output_folder, detector_backend='retinaface', align=True):\n",
    "    try:\n",
    "        faces = DeepFace.extract_faces(img_path=img, detector_backend=detector_backend, align=align)\n",
    "        for i, face_obj in enumerate(faces):\n",
    "            face = face_obj[\"face\"]\n",
    "            face_output_path = os.path.join(output_folder, image_path[:-4], f\"face_{i}.jpg\")\n",
    "            face.save(face_output_path)  # Sauvegarde le visage extrait\n",
    "    except Exception as e:\n",
    "        print(f\"Erreur lors du traitement de {image_path}: {e}\")"
   ]
  },
  {
   "cell_type": "code",
   "execution_count": 6,
   "metadata": {},
   "outputs": [
    {
     "name": "stderr",
     "output_type": "stream",
     "text": [
      "2024-11-27 18:04:20.090605: W tensorflow/core/common_runtime/gpu/gpu_bfc_allocator.cc:47] Overriding orig_value setting because the TF_FORCE_GPU_ALLOW_GROWTH environment variable is set. Original config value was 0.\n",
      "I0000 00:00:1732727060.090678   82932 gpu_device.cc:2022] Created device /job:localhost/replica:0/task:0/device:GPU:0 with 21563 MB memory:  -> device: 0, name: NVIDIA GeForce RTX 4090, pci bus id: 0000:01:00.0, compute capability: 8.9\n",
      "E0000 00:00:1732727062.211607   83333 cuda_dnn.cc:522] Loaded runtime CuDNN library: 9.1.0 but source was compiled with: 9.3.0.  CuDNN library needs to have matching major version and equal or higher minor version. If using a binary install, upgrade your CuDNN library.  If building from sources, make sure the library loaded at runtime is compatible with the version specified during compile configuration.\n",
      "2024-11-27 18:04:22.212014: I tensorflow/core/framework/local_rendezvous.cc:405] Local rendezvous is aborting with status: INTERNAL: No DNN support for stream\n",
      "\t [[{{node model/bn_data/FusedBatchNormV3}}]]\n"
     ]
    },
    {
     "name": "stdout",
     "output_type": "stream",
     "text": [
      "Erreur lors du traitement de data/24_10_09 Soir√©e oeno/IMG_2771.JPG: Graph execution error:\n",
      "\n",
      "Detected at node model/bn_data/FusedBatchNormV3 defined at (most recent call last):\n",
      "  File \"<frozen runpy>\", line 198, in _run_module_as_main\n",
      "\n",
      "  File \"<frozen runpy>\", line 88, in _run_code\n",
      "\n",
      "  File \"/home/alex/.local/lib/python3.12/site-packages/ipykernel_launcher.py\", line 18, in <module>\n",
      "\n",
      "  File \"/home/alex/.local/lib/python3.12/site-packages/traitlets/config/application.py\", line 1075, in launch_instance\n",
      "\n",
      "  File \"/home/alex/.local/lib/python3.12/site-packages/ipykernel/kernelapp.py\", line 739, in start\n",
      "\n",
      "  File \"/home/alex/.local/lib/python3.12/site-packages/tornado/platform/asyncio.py\", line 205, in start\n",
      "\n",
      "  File \"/usr/lib/python3.12/asyncio/base_events.py\", line 641, in run_forever\n",
      "\n",
      "  File \"/usr/lib/python3.12/asyncio/base_events.py\", line 1987, in _run_once\n",
      "\n",
      "  File \"/usr/lib/python3.12/asyncio/events.py\", line 88, in _run\n",
      "\n",
      "  File \"/home/alex/.local/lib/python3.12/site-packages/ipykernel/kernelbase.py\", line 545, in dispatch_queue\n",
      "\n",
      "  File \"/home/alex/.local/lib/python3.12/site-packages/ipykernel/kernelbase.py\", line 534, in process_one\n",
      "\n",
      "  File \"/home/alex/.local/lib/python3.12/site-packages/ipykernel/kernelbase.py\", line 437, in dispatch_shell\n",
      "\n",
      "  File \"/home/alex/.local/lib/python3.12/site-packages/ipykernel/ipkernel.py\", line 362, in execute_request\n",
      "\n",
      "  File \"/home/alex/.local/lib/python3.12/site-packages/ipykernel/kernelbase.py\", line 778, in execute_request\n",
      "\n",
      "  File \"/home/alex/.local/lib/python3.12/site-packages/ipykernel/ipkernel.py\", line 449, in do_execute\n",
      "\n",
      "  File \"/home/alex/.local/lib/python3.12/site-packages/ipykernel/zmqshell.py\", line 549, in run_cell\n",
      "\n",
      "  File \"/home/alex/.local/lib/python3.12/site-packages/IPython/core/interactiveshell.py\", line 3009, in run_cell\n",
      "\n",
      "  File \"/home/alex/.local/lib/python3.12/site-packages/IPython/core/interactiveshell.py\", line 3064, in _run_cell\n",
      "\n",
      "  File \"/home/alex/.local/lib/python3.12/site-packages/IPython/core/async_helpers.py\", line 129, in _pseudo_sync_runner\n",
      "\n",
      "  File \"/home/alex/.local/lib/python3.12/site-packages/IPython/core/interactiveshell.py\", line 3269, in run_cell_async\n",
      "\n",
      "  File \"/home/alex/.local/lib/python3.12/site-packages/IPython/core/interactiveshell.py\", line 3448, in run_ast_nodes\n",
      "\n",
      "  File \"/home/alex/.local/lib/python3.12/site-packages/IPython/core/interactiveshell.py\", line 3508, in run_code\n",
      "\n",
      "  File \"/tmp/ipykernel_82932/3687957463.py\", line 13, in <module>\n",
      "\n",
      "  File \"/tmp/ipykernel_82932/2126864146.py\", line 4, in extract_faces\n",
      "\n",
      "  File \"/home/alex/.local/lib/python3.12/site-packages/deepface/DeepFace.py\", line 549, in extract_faces\n",
      "\n",
      "  File \"/home/alex/.local/lib/python3.12/site-packages/deepface/modules/detection.py\", line 95, in extract_faces\n",
      "\n",
      "  File \"/home/alex/.local/lib/python3.12/site-packages/deepface/modules/detection.py\", line 234, in detect_faces\n",
      "\n",
      "  File \"/home/alex/.local/lib/python3.12/site-packages/deepface/models/face_detection/RetinaFace.py\", line 23, in detect_faces\n",
      "\n",
      "  File \"/home/alex/.local/lib/python3.12/site-packages/retinaface/RetinaFace.py\", line 123, in detect_faces\n",
      "\n",
      "  File \"/home/alex/.local/lib/python3.12/site-packages/tf_keras/src/engine/training.py\", line 553, in error_handler\n",
      "\n",
      "  File \"/home/alex/.local/lib/python3.12/site-packages/tf_keras/src/engine/training.py\", line 558, in error_handler\n",
      "\n",
      "  File \"/home/alex/.local/lib/python3.12/site-packages/tf_keras/src/engine/training.py\", line 588, in __call__\n",
      "\n",
      "  File \"/home/alex/.local/lib/python3.12/site-packages/tf_keras/src/utils/traceback_utils.py\", line 65, in error_handler\n",
      "\n",
      "  File \"/home/alex/.local/lib/python3.12/site-packages/tf_keras/src/engine/base_layer.py\", line 1142, in __call__\n",
      "\n",
      "  File \"/home/alex/.local/lib/python3.12/site-packages/tf_keras/src/utils/traceback_utils.py\", line 96, in error_handler\n",
      "\n",
      "  File \"/home/alex/.local/lib/python3.12/site-packages/tf_keras/src/engine/functional.py\", line 514, in call\n",
      "\n",
      "  File \"/home/alex/.local/lib/python3.12/site-packages/tf_keras/src/engine/functional.py\", line 671, in _run_internal_graph\n",
      "\n",
      "  File \"/home/alex/.local/lib/python3.12/site-packages/tf_keras/src/utils/traceback_utils.py\", line 65, in error_handler\n",
      "\n",
      "  File \"/home/alex/.local/lib/python3.12/site-packages/tf_keras/src/engine/base_layer.py\", line 1142, in __call__\n",
      "\n",
      "  File \"/home/alex/.local/lib/python3.12/site-packages/tf_keras/src/utils/traceback_utils.py\", line 96, in error_handler\n",
      "\n",
      "  File \"/home/alex/.local/lib/python3.12/site-packages/tf_keras/src/layers/normalization/batch_normalization.py\", line 597, in call\n",
      "\n",
      "  File \"/home/alex/.local/lib/python3.12/site-packages/tf_keras/src/layers/normalization/batch_normalization.py\", line 990, in _fused_batch_norm\n",
      "\n",
      "  File \"/home/alex/.local/lib/python3.12/site-packages/tf_keras/src/utils/control_flow_util.py\", line 108, in smart_cond\n",
      "\n",
      "  File \"/home/alex/.local/lib/python3.12/site-packages/tf_keras/src/layers/normalization/batch_normalization.py\", line 979, in _fused_batch_norm_inference\n",
      "\n",
      "No DNN support for stream\n",
      "\t [[{{node model/bn_data/FusedBatchNormV3}}]] [Op:__inference_function_8077]\n",
      "Erreur lors du traitement de data/24_10_09 Soir√©e oeno/IMG_2768.JPG: Graph execution error:\n",
      "\n",
      "Detected at node model/bn_data/FusedBatchNormV3 defined at (most recent call last):\n",
      "  File \"<frozen runpy>\", line 198, in _run_module_as_main\n",
      "\n",
      "  File \"<frozen runpy>\", line 88, in _run_code\n",
      "\n",
      "  File \"/home/alex/.local/lib/python3.12/site-packages/ipykernel_launcher.py\", line 18, in <module>\n",
      "\n",
      "  File \"/home/alex/.local/lib/python3.12/site-packages/traitlets/config/application.py\", line 1075, in launch_instance\n",
      "\n",
      "  File \"/home/alex/.local/lib/python3.12/site-packages/ipykernel/kernelapp.py\", line 739, in start\n",
      "\n",
      "  File \"/home/alex/.local/lib/python3.12/site-packages/tornado/platform/asyncio.py\", line 205, in start\n",
      "\n",
      "  File \"/usr/lib/python3.12/asyncio/base_events.py\", line 641, in run_forever\n",
      "\n",
      "  File \"/usr/lib/python3.12/asyncio/base_events.py\", line 1987, in _run_once\n",
      "\n",
      "  File \"/usr/lib/python3.12/asyncio/events.py\", line 88, in _run\n",
      "\n",
      "  File \"/home/alex/.local/lib/python3.12/site-packages/ipykernel/kernelbase.py\", line 545, in dispatch_queue\n",
      "\n",
      "  File \"/home/alex/.local/lib/python3.12/site-packages/ipykernel/kernelbase.py\", line 534, in process_one\n",
      "\n",
      "  File \"/home/alex/.local/lib/python3.12/site-packages/ipykernel/kernelbase.py\", line 437, in dispatch_shell\n",
      "\n",
      "  File \"/home/alex/.local/lib/python3.12/site-packages/ipykernel/ipkernel.py\", line 362, in execute_request\n",
      "\n",
      "  File \"/home/alex/.local/lib/python3.12/site-packages/ipykernel/kernelbase.py\", line 778, in execute_request\n",
      "\n",
      "  File \"/home/alex/.local/lib/python3.12/site-packages/ipykernel/ipkernel.py\", line 449, in do_execute\n",
      "\n",
      "  File \"/home/alex/.local/lib/python3.12/site-packages/ipykernel/zmqshell.py\", line 549, in run_cell\n",
      "\n",
      "  File \"/home/alex/.local/lib/python3.12/site-packages/IPython/core/interactiveshell.py\", line 3009, in run_cell\n",
      "\n",
      "  File \"/home/alex/.local/lib/python3.12/site-packages/IPython/core/interactiveshell.py\", line 3064, in _run_cell\n",
      "\n",
      "  File \"/home/alex/.local/lib/python3.12/site-packages/IPython/core/async_helpers.py\", line 129, in _pseudo_sync_runner\n",
      "\n",
      "  File \"/home/alex/.local/lib/python3.12/site-packages/IPython/core/interactiveshell.py\", line 3269, in run_cell_async\n",
      "\n",
      "  File \"/home/alex/.local/lib/python3.12/site-packages/IPython/core/interactiveshell.py\", line 3448, in run_ast_nodes\n",
      "\n",
      "  File \"/home/alex/.local/lib/python3.12/site-packages/IPython/core/interactiveshell.py\", line 3508, in run_code\n",
      "\n",
      "  File \"/tmp/ipykernel_82932/3687957463.py\", line 13, in <module>\n",
      "\n",
      "  File \"/tmp/ipykernel_82932/2126864146.py\", line 4, in extract_faces\n",
      "\n",
      "  File \"/home/alex/.local/lib/python3.12/site-packages/deepface/DeepFace.py\", line 549, in extract_faces\n",
      "\n",
      "  File \"/home/alex/.local/lib/python3.12/site-packages/deepface/modules/detection.py\", line 95, in extract_faces\n",
      "\n",
      "  File \"/home/alex/.local/lib/python3.12/site-packages/deepface/modules/detection.py\", line 234, in detect_faces\n",
      "\n",
      "  File \"/home/alex/.local/lib/python3.12/site-packages/deepface/models/face_detection/RetinaFace.py\", line 23, in detect_faces\n",
      "\n",
      "  File \"/home/alex/.local/lib/python3.12/site-packages/retinaface/RetinaFace.py\", line 123, in detect_faces\n",
      "\n",
      "  File \"/home/alex/.local/lib/python3.12/site-packages/tf_keras/src/engine/training.py\", line 553, in error_handler\n",
      "\n",
      "  File \"/home/alex/.local/lib/python3.12/site-packages/tf_keras/src/engine/training.py\", line 558, in error_handler\n",
      "\n",
      "  File \"/home/alex/.local/lib/python3.12/site-packages/tf_keras/src/engine/training.py\", line 588, in __call__\n",
      "\n",
      "  File \"/home/alex/.local/lib/python3.12/site-packages/tf_keras/src/utils/traceback_utils.py\", line 65, in error_handler\n",
      "\n",
      "  File \"/home/alex/.local/lib/python3.12/site-packages/tf_keras/src/engine/base_layer.py\", line 1142, in __call__\n",
      "\n",
      "  File \"/home/alex/.local/lib/python3.12/site-packages/tf_keras/src/utils/traceback_utils.py\", line 96, in error_handler\n",
      "\n",
      "  File \"/home/alex/.local/lib/python3.12/site-packages/tf_keras/src/engine/functional.py\", line 514, in call\n",
      "\n",
      "  File \"/home/alex/.local/lib/python3.12/site-packages/tf_keras/src/engine/functional.py\", line 671, in _run_internal_graph\n",
      "\n",
      "  File \"/home/alex/.local/lib/python3.12/site-packages/tf_keras/src/utils/traceback_utils.py\", line 65, in error_handler\n",
      "\n",
      "  File \"/home/alex/.local/lib/python3.12/site-packages/tf_keras/src/engine/base_layer.py\", line 1142, in __call__\n",
      "\n",
      "  File \"/home/alex/.local/lib/python3.12/site-packages/tf_keras/src/utils/traceback_utils.py\", line 96, in error_handler\n",
      "\n",
      "  File \"/home/alex/.local/lib/python3.12/site-packages/tf_keras/src/layers/normalization/batch_normalization.py\", line 597, in call\n",
      "\n",
      "  File \"/home/alex/.local/lib/python3.12/site-packages/tf_keras/src/layers/normalization/batch_normalization.py\", line 990, in _fused_batch_norm\n",
      "\n",
      "  File \"/home/alex/.local/lib/python3.12/site-packages/tf_keras/src/utils/control_flow_util.py\", line 108, in smart_cond\n",
      "\n",
      "  File \"/home/alex/.local/lib/python3.12/site-packages/tf_keras/src/layers/normalization/batch_normalization.py\", line 979, in _fused_batch_norm_inference\n",
      "\n",
      "No DNN support for stream\n",
      "\t [[{{node model/bn_data/FusedBatchNormV3}}]] [Op:__inference_function_8077]\n"
     ]
    },
    {
     "name": "stderr",
     "output_type": "stream",
     "text": [
      "E0000 00:00:1732727062.440427   83322 cuda_dnn.cc:522] Loaded runtime CuDNN library: 9.1.0 but source was compiled with: 9.3.0.  CuDNN library needs to have matching major version and equal or higher minor version. If using a binary install, upgrade your CuDNN library.  If building from sources, make sure the library loaded at runtime is compatible with the version specified during compile configuration.\n",
      "2024-11-27 18:04:22.440993: I tensorflow/core/framework/local_rendezvous.cc:405] Local rendezvous is aborting with status: INTERNAL: No DNN support for stream\n",
      "\t [[{{node model/bn_data/FusedBatchNormV3}}]]\n",
      "E0000 00:00:1732727062.688964   83322 cuda_dnn.cc:522] Loaded runtime CuDNN library: 9.1.0 but source was compiled with: 9.3.0.  CuDNN library needs to have matching major version and equal or higher minor version. If using a binary install, upgrade your CuDNN library.  If building from sources, make sure the library loaded at runtime is compatible with the version specified during compile configuration.\n",
      "E0000 00:00:1732727062.875864   83333 cuda_dnn.cc:522] Loaded runtime CuDNN library: 9.1.0 but source was compiled with: 9.3.0.  CuDNN library needs to have matching major version and equal or higher minor version. If using a binary install, upgrade your CuDNN library.  If building from sources, make sure the library loaded at runtime is compatible with the version specified during compile configuration.\n",
      "2024-11-27 18:04:22.876400: I tensorflow/core/framework/local_rendezvous.cc:405] Local rendezvous is aborting with status: INTERNAL: No DNN support for stream\n",
      "\t [[{{node model/bn_data/FusedBatchNormV3}}]]\n"
     ]
    },
    {
     "name": "stdout",
     "output_type": "stream",
     "text": [
      "Erreur lors du traitement de data/24_10_09 Soir√©e oeno/IMG_2801.JPG: Graph execution error:\n",
      "\n",
      "Detected at node model/bn_data/FusedBatchNormV3 defined at (most recent call last):\n",
      "  File \"<frozen runpy>\", line 198, in _run_module_as_main\n",
      "\n",
      "  File \"<frozen runpy>\", line 88, in _run_code\n",
      "\n",
      "  File \"/home/alex/.local/lib/python3.12/site-packages/ipykernel_launcher.py\", line 18, in <module>\n",
      "\n",
      "  File \"/home/alex/.local/lib/python3.12/site-packages/traitlets/config/application.py\", line 1075, in launch_instance\n",
      "\n",
      "  File \"/home/alex/.local/lib/python3.12/site-packages/ipykernel/kernelapp.py\", line 739, in start\n",
      "\n",
      "  File \"/home/alex/.local/lib/python3.12/site-packages/tornado/platform/asyncio.py\", line 205, in start\n",
      "\n",
      "  File \"/usr/lib/python3.12/asyncio/base_events.py\", line 641, in run_forever\n",
      "\n",
      "  File \"/usr/lib/python3.12/asyncio/base_events.py\", line 1987, in _run_once\n",
      "\n",
      "  File \"/usr/lib/python3.12/asyncio/events.py\", line 88, in _run\n",
      "\n",
      "  File \"/home/alex/.local/lib/python3.12/site-packages/ipykernel/kernelbase.py\", line 545, in dispatch_queue\n",
      "\n",
      "  File \"/home/alex/.local/lib/python3.12/site-packages/ipykernel/kernelbase.py\", line 534, in process_one\n",
      "\n",
      "  File \"/home/alex/.local/lib/python3.12/site-packages/ipykernel/kernelbase.py\", line 437, in dispatch_shell\n",
      "\n",
      "  File \"/home/alex/.local/lib/python3.12/site-packages/ipykernel/ipkernel.py\", line 362, in execute_request\n",
      "\n",
      "  File \"/home/alex/.local/lib/python3.12/site-packages/ipykernel/kernelbase.py\", line 778, in execute_request\n",
      "\n",
      "  File \"/home/alex/.local/lib/python3.12/site-packages/ipykernel/ipkernel.py\", line 449, in do_execute\n",
      "\n",
      "  File \"/home/alex/.local/lib/python3.12/site-packages/ipykernel/zmqshell.py\", line 549, in run_cell\n",
      "\n",
      "  File \"/home/alex/.local/lib/python3.12/site-packages/IPython/core/interactiveshell.py\", line 3009, in run_cell\n",
      "\n",
      "  File \"/home/alex/.local/lib/python3.12/site-packages/IPython/core/interactiveshell.py\", line 3064, in _run_cell\n",
      "\n",
      "  File \"/home/alex/.local/lib/python3.12/site-packages/IPython/core/async_helpers.py\", line 129, in _pseudo_sync_runner\n",
      "\n",
      "  File \"/home/alex/.local/lib/python3.12/site-packages/IPython/core/interactiveshell.py\", line 3269, in run_cell_async\n",
      "\n",
      "  File \"/home/alex/.local/lib/python3.12/site-packages/IPython/core/interactiveshell.py\", line 3448, in run_ast_nodes\n",
      "\n",
      "  File \"/home/alex/.local/lib/python3.12/site-packages/IPython/core/interactiveshell.py\", line 3508, in run_code\n",
      "\n",
      "  File \"/tmp/ipykernel_82932/3687957463.py\", line 13, in <module>\n",
      "\n",
      "  File \"/tmp/ipykernel_82932/2126864146.py\", line 4, in extract_faces\n",
      "\n",
      "  File \"/home/alex/.local/lib/python3.12/site-packages/deepface/DeepFace.py\", line 549, in extract_faces\n",
      "\n",
      "  File \"/home/alex/.local/lib/python3.12/site-packages/deepface/modules/detection.py\", line 95, in extract_faces\n",
      "\n",
      "  File \"/home/alex/.local/lib/python3.12/site-packages/deepface/modules/detection.py\", line 234, in detect_faces\n",
      "\n",
      "  File \"/home/alex/.local/lib/python3.12/site-packages/deepface/models/face_detection/RetinaFace.py\", line 23, in detect_faces\n",
      "\n",
      "  File \"/home/alex/.local/lib/python3.12/site-packages/retinaface/RetinaFace.py\", line 123, in detect_faces\n",
      "\n",
      "  File \"/home/alex/.local/lib/python3.12/site-packages/tf_keras/src/engine/training.py\", line 553, in error_handler\n",
      "\n",
      "  File \"/home/alex/.local/lib/python3.12/site-packages/tf_keras/src/engine/training.py\", line 558, in error_handler\n",
      "\n",
      "  File \"/home/alex/.local/lib/python3.12/site-packages/tf_keras/src/engine/training.py\", line 588, in __call__\n",
      "\n",
      "  File \"/home/alex/.local/lib/python3.12/site-packages/tf_keras/src/utils/traceback_utils.py\", line 65, in error_handler\n",
      "\n",
      "  File \"/home/alex/.local/lib/python3.12/site-packages/tf_keras/src/engine/base_layer.py\", line 1142, in __call__\n",
      "\n",
      "  File \"/home/alex/.local/lib/python3.12/site-packages/tf_keras/src/utils/traceback_utils.py\", line 96, in error_handler\n",
      "\n",
      "  File \"/home/alex/.local/lib/python3.12/site-packages/tf_keras/src/engine/functional.py\", line 514, in call\n",
      "\n",
      "  File \"/home/alex/.local/lib/python3.12/site-packages/tf_keras/src/engine/functional.py\", line 671, in _run_internal_graph\n",
      "\n",
      "  File \"/home/alex/.local/lib/python3.12/site-packages/tf_keras/src/utils/traceback_utils.py\", line 65, in error_handler\n",
      "\n",
      "  File \"/home/alex/.local/lib/python3.12/site-packages/tf_keras/src/engine/base_layer.py\", line 1142, in __call__\n",
      "\n",
      "  File \"/home/alex/.local/lib/python3.12/site-packages/tf_keras/src/utils/traceback_utils.py\", line 96, in error_handler\n",
      "\n",
      "  File \"/home/alex/.local/lib/python3.12/site-packages/tf_keras/src/layers/normalization/batch_normalization.py\", line 597, in call\n",
      "\n",
      "  File \"/home/alex/.local/lib/python3.12/site-packages/tf_keras/src/layers/normalization/batch_normalization.py\", line 990, in _fused_batch_norm\n",
      "\n",
      "  File \"/home/alex/.local/lib/python3.12/site-packages/tf_keras/src/utils/control_flow_util.py\", line 108, in smart_cond\n",
      "\n",
      "  File \"/home/alex/.local/lib/python3.12/site-packages/tf_keras/src/layers/normalization/batch_normalization.py\", line 979, in _fused_batch_norm_inference\n",
      "\n",
      "No DNN support for stream\n",
      "\t [[{{node model/bn_data/FusedBatchNormV3}}]] [Op:__inference_function_8077]\n",
      "Erreur lors du traitement de data/24_10_09 Soir√©e oeno/IMG_2744.JPG: Graph execution error:\n",
      "\n",
      "Detected at node model/bn_data/FusedBatchNormV3 defined at (most recent call last):\n",
      "  File \"<frozen runpy>\", line 198, in _run_module_as_main\n",
      "\n",
      "  File \"<frozen runpy>\", line 88, in _run_code\n",
      "\n",
      "  File \"/home/alex/.local/lib/python3.12/site-packages/ipykernel_launcher.py\", line 18, in <module>\n",
      "\n",
      "  File \"/home/alex/.local/lib/python3.12/site-packages/traitlets/config/application.py\", line 1075, in launch_instance\n",
      "\n",
      "  File \"/home/alex/.local/lib/python3.12/site-packages/ipykernel/kernelapp.py\", line 739, in start\n",
      "\n",
      "  File \"/home/alex/.local/lib/python3.12/site-packages/tornado/platform/asyncio.py\", line 205, in start\n",
      "\n",
      "  File \"/usr/lib/python3.12/asyncio/base_events.py\", line 641, in run_forever\n",
      "\n",
      "  File \"/usr/lib/python3.12/asyncio/base_events.py\", line 1987, in _run_once\n",
      "\n",
      "  File \"/usr/lib/python3.12/asyncio/events.py\", line 88, in _run\n",
      "\n",
      "  File \"/home/alex/.local/lib/python3.12/site-packages/ipykernel/kernelbase.py\", line 545, in dispatch_queue\n",
      "\n",
      "  File \"/home/alex/.local/lib/python3.12/site-packages/ipykernel/kernelbase.py\", line 534, in process_one\n",
      "\n",
      "  File \"/home/alex/.local/lib/python3.12/site-packages/ipykernel/kernelbase.py\", line 437, in dispatch_shell\n",
      "\n",
      "  File \"/home/alex/.local/lib/python3.12/site-packages/ipykernel/ipkernel.py\", line 362, in execute_request\n",
      "\n",
      "  File \"/home/alex/.local/lib/python3.12/site-packages/ipykernel/kernelbase.py\", line 778, in execute_request\n",
      "\n",
      "  File \"/home/alex/.local/lib/python3.12/site-packages/ipykernel/ipkernel.py\", line 449, in do_execute\n",
      "\n",
      "  File \"/home/alex/.local/lib/python3.12/site-packages/ipykernel/zmqshell.py\", line 549, in run_cell\n",
      "\n",
      "  File \"/home/alex/.local/lib/python3.12/site-packages/IPython/core/interactiveshell.py\", line 3009, in run_cell\n",
      "\n",
      "  File \"/home/alex/.local/lib/python3.12/site-packages/IPython/core/interactiveshell.py\", line 3064, in _run_cell\n",
      "\n",
      "  File \"/home/alex/.local/lib/python3.12/site-packages/IPython/core/async_helpers.py\", line 129, in _pseudo_sync_runner\n",
      "\n",
      "  File \"/home/alex/.local/lib/python3.12/site-packages/IPython/core/interactiveshell.py\", line 3269, in run_cell_async\n",
      "\n",
      "  File \"/home/alex/.local/lib/python3.12/site-packages/IPython/core/interactiveshell.py\", line 3448, in run_ast_nodes\n",
      "\n",
      "  File \"/home/alex/.local/lib/python3.12/site-packages/IPython/core/interactiveshell.py\", line 3508, in run_code\n",
      "\n",
      "  File \"/tmp/ipykernel_82932/3687957463.py\", line 13, in <module>\n",
      "\n",
      "  File \"/tmp/ipykernel_82932/2126864146.py\", line 4, in extract_faces\n",
      "\n",
      "  File \"/home/alex/.local/lib/python3.12/site-packages/deepface/DeepFace.py\", line 549, in extract_faces\n",
      "\n",
      "  File \"/home/alex/.local/lib/python3.12/site-packages/deepface/modules/detection.py\", line 95, in extract_faces\n",
      "\n",
      "  File \"/home/alex/.local/lib/python3.12/site-packages/deepface/modules/detection.py\", line 234, in detect_faces\n",
      "\n",
      "  File \"/home/alex/.local/lib/python3.12/site-packages/deepface/models/face_detection/RetinaFace.py\", line 23, in detect_faces\n",
      "\n",
      "  File \"/home/alex/.local/lib/python3.12/site-packages/retinaface/RetinaFace.py\", line 123, in detect_faces\n",
      "\n",
      "  File \"/home/alex/.local/lib/python3.12/site-packages/tf_keras/src/engine/training.py\", line 553, in error_handler\n",
      "\n",
      "  File \"/home/alex/.local/lib/python3.12/site-packages/tf_keras/src/engine/training.py\", line 558, in error_handler\n",
      "\n",
      "  File \"/home/alex/.local/lib/python3.12/site-packages/tf_keras/src/engine/training.py\", line 588, in __call__\n",
      "\n",
      "  File \"/home/alex/.local/lib/python3.12/site-packages/tf_keras/src/utils/traceback_utils.py\", line 65, in error_handler\n",
      "\n",
      "  File \"/home/alex/.local/lib/python3.12/site-packages/tf_keras/src/engine/base_layer.py\", line 1142, in __call__\n",
      "\n",
      "  File \"/home/alex/.local/lib/python3.12/site-packages/tf_keras/src/utils/traceback_utils.py\", line 96, in error_handler\n",
      "\n",
      "  File \"/home/alex/.local/lib/python3.12/site-packages/tf_keras/src/engine/functional.py\", line 514, in call\n",
      "\n",
      "  File \"/home/alex/.local/lib/python3.12/site-packages/tf_keras/src/engine/functional.py\", line 671, in _run_internal_graph\n",
      "\n",
      "  File \"/home/alex/.local/lib/python3.12/site-packages/tf_keras/src/utils/traceback_utils.py\", line 65, in error_handler\n",
      "\n",
      "  File \"/home/alex/.local/lib/python3.12/site-packages/tf_keras/src/engine/base_layer.py\", line 1142, in __call__\n",
      "\n",
      "  File \"/home/alex/.local/lib/python3.12/site-packages/tf_keras/src/utils/traceback_utils.py\", line 96, in error_handler\n",
      "\n",
      "  File \"/home/alex/.local/lib/python3.12/site-packages/tf_keras/src/layers/normalization/batch_normalization.py\", line 597, in call\n",
      "\n",
      "  File \"/home/alex/.local/lib/python3.12/site-packages/tf_keras/src/layers/normalization/batch_normalization.py\", line 990, in _fused_batch_norm\n",
      "\n",
      "  File \"/home/alex/.local/lib/python3.12/site-packages/tf_keras/src/utils/control_flow_util.py\", line 108, in smart_cond\n",
      "\n",
      "  File \"/home/alex/.local/lib/python3.12/site-packages/tf_keras/src/layers/normalization/batch_normalization.py\", line 979, in _fused_batch_norm_inference\n",
      "\n",
      "No DNN support for stream\n",
      "\t [[{{node model/bn_data/FusedBatchNormV3}}]] [Op:__inference_function_8077]\n"
     ]
    },
    {
     "name": "stderr",
     "output_type": "stream",
     "text": [
      "E0000 00:00:1732727063.062820   83322 cuda_dnn.cc:522] Loaded runtime CuDNN library: 9.1.0 but source was compiled with: 9.3.0.  CuDNN library needs to have matching major version and equal or higher minor version. If using a binary install, upgrade your CuDNN library.  If building from sources, make sure the library loaded at runtime is compatible with the version specified during compile configuration.\n"
     ]
    },
    {
     "name": "stdout",
     "output_type": "stream",
     "text": [
      "Erreur lors du traitement de data/24_10_09 Soir√©e oeno/IMG_2773.JPG: Graph execution error:\n",
      "\n",
      "Detected at node model/bn_data/FusedBatchNormV3 defined at (most recent call last):\n",
      "  File \"<frozen runpy>\", line 198, in _run_module_as_main\n",
      "\n",
      "  File \"<frozen runpy>\", line 88, in _run_code\n",
      "\n",
      "  File \"/home/alex/.local/lib/python3.12/site-packages/ipykernel_launcher.py\", line 18, in <module>\n",
      "\n",
      "  File \"/home/alex/.local/lib/python3.12/site-packages/traitlets/config/application.py\", line 1075, in launch_instance\n",
      "\n",
      "  File \"/home/alex/.local/lib/python3.12/site-packages/ipykernel/kernelapp.py\", line 739, in start\n",
      "\n",
      "  File \"/home/alex/.local/lib/python3.12/site-packages/tornado/platform/asyncio.py\", line 205, in start\n",
      "\n",
      "  File \"/usr/lib/python3.12/asyncio/base_events.py\", line 641, in run_forever\n",
      "\n",
      "  File \"/usr/lib/python3.12/asyncio/base_events.py\", line 1987, in _run_once\n",
      "\n",
      "  File \"/usr/lib/python3.12/asyncio/events.py\", line 88, in _run\n",
      "\n",
      "  File \"/home/alex/.local/lib/python3.12/site-packages/ipykernel/kernelbase.py\", line 545, in dispatch_queue\n",
      "\n",
      "  File \"/home/alex/.local/lib/python3.12/site-packages/ipykernel/kernelbase.py\", line 534, in process_one\n",
      "\n",
      "  File \"/home/alex/.local/lib/python3.12/site-packages/ipykernel/kernelbase.py\", line 437, in dispatch_shell\n",
      "\n",
      "  File \"/home/alex/.local/lib/python3.12/site-packages/ipykernel/ipkernel.py\", line 362, in execute_request\n",
      "\n",
      "  File \"/home/alex/.local/lib/python3.12/site-packages/ipykernel/kernelbase.py\", line 778, in execute_request\n",
      "\n",
      "  File \"/home/alex/.local/lib/python3.12/site-packages/ipykernel/ipkernel.py\", line 449, in do_execute\n",
      "\n",
      "  File \"/home/alex/.local/lib/python3.12/site-packages/ipykernel/zmqshell.py\", line 549, in run_cell\n",
      "\n",
      "  File \"/home/alex/.local/lib/python3.12/site-packages/IPython/core/interactiveshell.py\", line 3009, in run_cell\n",
      "\n",
      "  File \"/home/alex/.local/lib/python3.12/site-packages/IPython/core/interactiveshell.py\", line 3064, in _run_cell\n",
      "\n",
      "  File \"/home/alex/.local/lib/python3.12/site-packages/IPython/core/async_helpers.py\", line 129, in _pseudo_sync_runner\n",
      "\n",
      "  File \"/home/alex/.local/lib/python3.12/site-packages/IPython/core/interactiveshell.py\", line 3269, in run_cell_async\n",
      "\n",
      "  File \"/home/alex/.local/lib/python3.12/site-packages/IPython/core/interactiveshell.py\", line 3448, in run_ast_nodes\n",
      "\n",
      "  File \"/home/alex/.local/lib/python3.12/site-packages/IPython/core/interactiveshell.py\", line 3508, in run_code\n",
      "\n",
      "  File \"/tmp/ipykernel_82932/3687957463.py\", line 13, in <module>\n",
      "\n",
      "  File \"/tmp/ipykernel_82932/2126864146.py\", line 4, in extract_faces\n",
      "\n",
      "  File \"/home/alex/.local/lib/python3.12/site-packages/deepface/DeepFace.py\", line 549, in extract_faces\n",
      "\n",
      "  File \"/home/alex/.local/lib/python3.12/site-packages/deepface/modules/detection.py\", line 95, in extract_faces\n",
      "\n",
      "  File \"/home/alex/.local/lib/python3.12/site-packages/deepface/modules/detection.py\", line 234, in detect_faces\n",
      "\n",
      "  File \"/home/alex/.local/lib/python3.12/site-packages/deepface/models/face_detection/RetinaFace.py\", line 23, in detect_faces\n",
      "\n",
      "  File \"/home/alex/.local/lib/python3.12/site-packages/retinaface/RetinaFace.py\", line 123, in detect_faces\n",
      "\n",
      "  File \"/home/alex/.local/lib/python3.12/site-packages/tf_keras/src/engine/training.py\", line 553, in error_handler\n",
      "\n",
      "  File \"/home/alex/.local/lib/python3.12/site-packages/tf_keras/src/engine/training.py\", line 558, in error_handler\n",
      "\n",
      "  File \"/home/alex/.local/lib/python3.12/site-packages/tf_keras/src/engine/training.py\", line 588, in __call__\n",
      "\n",
      "  File \"/home/alex/.local/lib/python3.12/site-packages/tf_keras/src/utils/traceback_utils.py\", line 65, in error_handler\n",
      "\n",
      "  File \"/home/alex/.local/lib/python3.12/site-packages/tf_keras/src/engine/base_layer.py\", line 1142, in __call__\n",
      "\n",
      "  File \"/home/alex/.local/lib/python3.12/site-packages/tf_keras/src/utils/traceback_utils.py\", line 96, in error_handler\n",
      "\n",
      "  File \"/home/alex/.local/lib/python3.12/site-packages/tf_keras/src/engine/functional.py\", line 514, in call\n",
      "\n",
      "  File \"/home/alex/.local/lib/python3.12/site-packages/tf_keras/src/engine/functional.py\", line 671, in _run_internal_graph\n",
      "\n",
      "  File \"/home/alex/.local/lib/python3.12/site-packages/tf_keras/src/utils/traceback_utils.py\", line 65, in error_handler\n",
      "\n",
      "  File \"/home/alex/.local/lib/python3.12/site-packages/tf_keras/src/engine/base_layer.py\", line 1142, in __call__\n",
      "\n",
      "  File \"/home/alex/.local/lib/python3.12/site-packages/tf_keras/src/utils/traceback_utils.py\", line 96, in error_handler\n",
      "\n",
      "  File \"/home/alex/.local/lib/python3.12/site-packages/tf_keras/src/layers/normalization/batch_normalization.py\", line 597, in call\n",
      "\n",
      "  File \"/home/alex/.local/lib/python3.12/site-packages/tf_keras/src/layers/normalization/batch_normalization.py\", line 990, in _fused_batch_norm\n",
      "\n",
      "  File \"/home/alex/.local/lib/python3.12/site-packages/tf_keras/src/utils/control_flow_util.py\", line 108, in smart_cond\n",
      "\n",
      "  File \"/home/alex/.local/lib/python3.12/site-packages/tf_keras/src/layers/normalization/batch_normalization.py\", line 979, in _fused_batch_norm_inference\n",
      "\n",
      "No DNN support for stream\n",
      "\t [[{{node model/bn_data/FusedBatchNormV3}}]] [Op:__inference_function_8077]\n"
     ]
    },
    {
     "name": "stderr",
     "output_type": "stream",
     "text": [
      "E0000 00:00:1732727063.286230   83333 cuda_dnn.cc:522] Loaded runtime CuDNN library: 9.1.0 but source was compiled with: 9.3.0.  CuDNN library needs to have matching major version and equal or higher minor version. If using a binary install, upgrade your CuDNN library.  If building from sources, make sure the library loaded at runtime is compatible with the version specified during compile configuration.\n"
     ]
    },
    {
     "name": "stdout",
     "output_type": "stream",
     "text": [
      "Erreur lors du traitement de data/24_10_09 Soir√©e oeno/IMG_2813.JPG: Graph execution error:\n",
      "\n",
      "Detected at node model/bn_data/FusedBatchNormV3 defined at (most recent call last):\n",
      "  File \"<frozen runpy>\", line 198, in _run_module_as_main\n",
      "\n",
      "  File \"<frozen runpy>\", line 88, in _run_code\n",
      "\n",
      "  File \"/home/alex/.local/lib/python3.12/site-packages/ipykernel_launcher.py\", line 18, in <module>\n",
      "\n",
      "  File \"/home/alex/.local/lib/python3.12/site-packages/traitlets/config/application.py\", line 1075, in launch_instance\n",
      "\n",
      "  File \"/home/alex/.local/lib/python3.12/site-packages/ipykernel/kernelapp.py\", line 739, in start\n",
      "\n",
      "  File \"/home/alex/.local/lib/python3.12/site-packages/tornado/platform/asyncio.py\", line 205, in start\n",
      "\n",
      "  File \"/usr/lib/python3.12/asyncio/base_events.py\", line 641, in run_forever\n",
      "\n",
      "  File \"/usr/lib/python3.12/asyncio/base_events.py\", line 1987, in _run_once\n",
      "\n",
      "  File \"/usr/lib/python3.12/asyncio/events.py\", line 88, in _run\n",
      "\n",
      "  File \"/home/alex/.local/lib/python3.12/site-packages/ipykernel/kernelbase.py\", line 545, in dispatch_queue\n",
      "\n",
      "  File \"/home/alex/.local/lib/python3.12/site-packages/ipykernel/kernelbase.py\", line 534, in process_one\n",
      "\n",
      "  File \"/home/alex/.local/lib/python3.12/site-packages/ipykernel/kernelbase.py\", line 437, in dispatch_shell\n",
      "\n",
      "  File \"/home/alex/.local/lib/python3.12/site-packages/ipykernel/ipkernel.py\", line 362, in execute_request\n",
      "\n",
      "  File \"/home/alex/.local/lib/python3.12/site-packages/ipykernel/kernelbase.py\", line 778, in execute_request\n",
      "\n",
      "  File \"/home/alex/.local/lib/python3.12/site-packages/ipykernel/ipkernel.py\", line 449, in do_execute\n",
      "\n",
      "  File \"/home/alex/.local/lib/python3.12/site-packages/ipykernel/zmqshell.py\", line 549, in run_cell\n",
      "\n",
      "  File \"/home/alex/.local/lib/python3.12/site-packages/IPython/core/interactiveshell.py\", line 3009, in run_cell\n",
      "\n",
      "  File \"/home/alex/.local/lib/python3.12/site-packages/IPython/core/interactiveshell.py\", line 3064, in _run_cell\n",
      "\n",
      "  File \"/home/alex/.local/lib/python3.12/site-packages/IPython/core/async_helpers.py\", line 129, in _pseudo_sync_runner\n",
      "\n",
      "  File \"/home/alex/.local/lib/python3.12/site-packages/IPython/core/interactiveshell.py\", line 3269, in run_cell_async\n",
      "\n",
      "  File \"/home/alex/.local/lib/python3.12/site-packages/IPython/core/interactiveshell.py\", line 3448, in run_ast_nodes\n",
      "\n",
      "  File \"/home/alex/.local/lib/python3.12/site-packages/IPython/core/interactiveshell.py\", line 3508, in run_code\n",
      "\n",
      "  File \"/tmp/ipykernel_82932/3687957463.py\", line 13, in <module>\n",
      "\n",
      "  File \"/tmp/ipykernel_82932/2126864146.py\", line 4, in extract_faces\n",
      "\n",
      "  File \"/home/alex/.local/lib/python3.12/site-packages/deepface/DeepFace.py\", line 549, in extract_faces\n",
      "\n",
      "  File \"/home/alex/.local/lib/python3.12/site-packages/deepface/modules/detection.py\", line 95, in extract_faces\n",
      "\n",
      "  File \"/home/alex/.local/lib/python3.12/site-packages/deepface/modules/detection.py\", line 234, in detect_faces\n",
      "\n",
      "  File \"/home/alex/.local/lib/python3.12/site-packages/deepface/models/face_detection/RetinaFace.py\", line 23, in detect_faces\n",
      "\n",
      "  File \"/home/alex/.local/lib/python3.12/site-packages/retinaface/RetinaFace.py\", line 123, in detect_faces\n",
      "\n",
      "  File \"/home/alex/.local/lib/python3.12/site-packages/tf_keras/src/engine/training.py\", line 553, in error_handler\n",
      "\n",
      "  File \"/home/alex/.local/lib/python3.12/site-packages/tf_keras/src/engine/training.py\", line 558, in error_handler\n",
      "\n",
      "  File \"/home/alex/.local/lib/python3.12/site-packages/tf_keras/src/engine/training.py\", line 588, in __call__\n",
      "\n",
      "  File \"/home/alex/.local/lib/python3.12/site-packages/tf_keras/src/utils/traceback_utils.py\", line 65, in error_handler\n",
      "\n",
      "  File \"/home/alex/.local/lib/python3.12/site-packages/tf_keras/src/engine/base_layer.py\", line 1142, in __call__\n",
      "\n",
      "  File \"/home/alex/.local/lib/python3.12/site-packages/tf_keras/src/utils/traceback_utils.py\", line 96, in error_handler\n",
      "\n",
      "  File \"/home/alex/.local/lib/python3.12/site-packages/tf_keras/src/engine/functional.py\", line 514, in call\n",
      "\n",
      "  File \"/home/alex/.local/lib/python3.12/site-packages/tf_keras/src/engine/functional.py\", line 671, in _run_internal_graph\n",
      "\n",
      "  File \"/home/alex/.local/lib/python3.12/site-packages/tf_keras/src/utils/traceback_utils.py\", line 65, in error_handler\n",
      "\n",
      "  File \"/home/alex/.local/lib/python3.12/site-packages/tf_keras/src/engine/base_layer.py\", line 1142, in __call__\n",
      "\n",
      "  File \"/home/alex/.local/lib/python3.12/site-packages/tf_keras/src/utils/traceback_utils.py\", line 96, in error_handler\n",
      "\n",
      "  File \"/home/alex/.local/lib/python3.12/site-packages/tf_keras/src/layers/normalization/batch_normalization.py\", line 597, in call\n",
      "\n",
      "  File \"/home/alex/.local/lib/python3.12/site-packages/tf_keras/src/layers/normalization/batch_normalization.py\", line 990, in _fused_batch_norm\n",
      "\n",
      "  File \"/home/alex/.local/lib/python3.12/site-packages/tf_keras/src/utils/control_flow_util.py\", line 108, in smart_cond\n",
      "\n",
      "  File \"/home/alex/.local/lib/python3.12/site-packages/tf_keras/src/layers/normalization/batch_normalization.py\", line 979, in _fused_batch_norm_inference\n",
      "\n",
      "No DNN support for stream\n",
      "\t [[{{node model/bn_data/FusedBatchNormV3}}]] [Op:__inference_function_8077]\n"
     ]
    },
    {
     "name": "stderr",
     "output_type": "stream",
     "text": [
      "E0000 00:00:1732727063.495758   83322 cuda_dnn.cc:522] Loaded runtime CuDNN library: 9.1.0 but source was compiled with: 9.3.0.  CuDNN library needs to have matching major version and equal or higher minor version. If using a binary install, upgrade your CuDNN library.  If building from sources, make sure the library loaded at runtime is compatible with the version specified during compile configuration.\n",
      "E0000 00:00:1732727063.695289   83333 cuda_dnn.cc:522] Loaded runtime CuDNN library: 9.1.0 but source was compiled with: 9.3.0.  CuDNN library needs to have matching major version and equal or higher minor version. If using a binary install, upgrade your CuDNN library.  If building from sources, make sure the library loaded at runtime is compatible with the version specified during compile configuration.\n",
      "2024-11-27 18:04:23.695710: I tensorflow/core/framework/local_rendezvous.cc:405] Local rendezvous is aborting with status: INTERNAL: No DNN support for stream\n",
      "\t [[{{node model/bn_data/FusedBatchNormV3}}]]\n"
     ]
    },
    {
     "name": "stdout",
     "output_type": "stream",
     "text": [
      "Erreur lors du traitement de data/24_10_09 Soir√©e oeno/IMG_2777.JPG: Graph execution error:\n",
      "\n",
      "Detected at node model/bn_data/FusedBatchNormV3 defined at (most recent call last):\n",
      "  File \"<frozen runpy>\", line 198, in _run_module_as_main\n",
      "\n",
      "  File \"<frozen runpy>\", line 88, in _run_code\n",
      "\n",
      "  File \"/home/alex/.local/lib/python3.12/site-packages/ipykernel_launcher.py\", line 18, in <module>\n",
      "\n",
      "  File \"/home/alex/.local/lib/python3.12/site-packages/traitlets/config/application.py\", line 1075, in launch_instance\n",
      "\n",
      "  File \"/home/alex/.local/lib/python3.12/site-packages/ipykernel/kernelapp.py\", line 739, in start\n",
      "\n",
      "  File \"/home/alex/.local/lib/python3.12/site-packages/tornado/platform/asyncio.py\", line 205, in start\n",
      "\n",
      "  File \"/usr/lib/python3.12/asyncio/base_events.py\", line 641, in run_forever\n",
      "\n",
      "  File \"/usr/lib/python3.12/asyncio/base_events.py\", line 1987, in _run_once\n",
      "\n",
      "  File \"/usr/lib/python3.12/asyncio/events.py\", line 88, in _run\n",
      "\n",
      "  File \"/home/alex/.local/lib/python3.12/site-packages/ipykernel/kernelbase.py\", line 545, in dispatch_queue\n",
      "\n",
      "  File \"/home/alex/.local/lib/python3.12/site-packages/ipykernel/kernelbase.py\", line 534, in process_one\n",
      "\n",
      "  File \"/home/alex/.local/lib/python3.12/site-packages/ipykernel/kernelbase.py\", line 437, in dispatch_shell\n",
      "\n",
      "  File \"/home/alex/.local/lib/python3.12/site-packages/ipykernel/ipkernel.py\", line 362, in execute_request\n",
      "\n",
      "  File \"/home/alex/.local/lib/python3.12/site-packages/ipykernel/kernelbase.py\", line 778, in execute_request\n",
      "\n",
      "  File \"/home/alex/.local/lib/python3.12/site-packages/ipykernel/ipkernel.py\", line 449, in do_execute\n",
      "\n",
      "  File \"/home/alex/.local/lib/python3.12/site-packages/ipykernel/zmqshell.py\", line 549, in run_cell\n",
      "\n",
      "  File \"/home/alex/.local/lib/python3.12/site-packages/IPython/core/interactiveshell.py\", line 3009, in run_cell\n",
      "\n",
      "  File \"/home/alex/.local/lib/python3.12/site-packages/IPython/core/interactiveshell.py\", line 3064, in _run_cell\n",
      "\n",
      "  File \"/home/alex/.local/lib/python3.12/site-packages/IPython/core/async_helpers.py\", line 129, in _pseudo_sync_runner\n",
      "\n",
      "  File \"/home/alex/.local/lib/python3.12/site-packages/IPython/core/interactiveshell.py\", line 3269, in run_cell_async\n",
      "\n",
      "  File \"/home/alex/.local/lib/python3.12/site-packages/IPython/core/interactiveshell.py\", line 3448, in run_ast_nodes\n",
      "\n",
      "  File \"/home/alex/.local/lib/python3.12/site-packages/IPython/core/interactiveshell.py\", line 3508, in run_code\n",
      "\n",
      "  File \"/tmp/ipykernel_82932/3687957463.py\", line 13, in <module>\n",
      "\n",
      "  File \"/tmp/ipykernel_82932/2126864146.py\", line 4, in extract_faces\n",
      "\n",
      "  File \"/home/alex/.local/lib/python3.12/site-packages/deepface/DeepFace.py\", line 549, in extract_faces\n",
      "\n",
      "  File \"/home/alex/.local/lib/python3.12/site-packages/deepface/modules/detection.py\", line 95, in extract_faces\n",
      "\n",
      "  File \"/home/alex/.local/lib/python3.12/site-packages/deepface/modules/detection.py\", line 234, in detect_faces\n",
      "\n",
      "  File \"/home/alex/.local/lib/python3.12/site-packages/deepface/models/face_detection/RetinaFace.py\", line 23, in detect_faces\n",
      "\n",
      "  File \"/home/alex/.local/lib/python3.12/site-packages/retinaface/RetinaFace.py\", line 123, in detect_faces\n",
      "\n",
      "  File \"/home/alex/.local/lib/python3.12/site-packages/tf_keras/src/engine/training.py\", line 553, in error_handler\n",
      "\n",
      "  File \"/home/alex/.local/lib/python3.12/site-packages/tf_keras/src/engine/training.py\", line 558, in error_handler\n",
      "\n",
      "  File \"/home/alex/.local/lib/python3.12/site-packages/tf_keras/src/engine/training.py\", line 588, in __call__\n",
      "\n",
      "  File \"/home/alex/.local/lib/python3.12/site-packages/tf_keras/src/utils/traceback_utils.py\", line 65, in error_handler\n",
      "\n",
      "  File \"/home/alex/.local/lib/python3.12/site-packages/tf_keras/src/engine/base_layer.py\", line 1142, in __call__\n",
      "\n",
      "  File \"/home/alex/.local/lib/python3.12/site-packages/tf_keras/src/utils/traceback_utils.py\", line 96, in error_handler\n",
      "\n",
      "  File \"/home/alex/.local/lib/python3.12/site-packages/tf_keras/src/engine/functional.py\", line 514, in call\n",
      "\n",
      "  File \"/home/alex/.local/lib/python3.12/site-packages/tf_keras/src/engine/functional.py\", line 671, in _run_internal_graph\n",
      "\n",
      "  File \"/home/alex/.local/lib/python3.12/site-packages/tf_keras/src/utils/traceback_utils.py\", line 65, in error_handler\n",
      "\n",
      "  File \"/home/alex/.local/lib/python3.12/site-packages/tf_keras/src/engine/base_layer.py\", line 1142, in __call__\n",
      "\n",
      "  File \"/home/alex/.local/lib/python3.12/site-packages/tf_keras/src/utils/traceback_utils.py\", line 96, in error_handler\n",
      "\n",
      "  File \"/home/alex/.local/lib/python3.12/site-packages/tf_keras/src/layers/normalization/batch_normalization.py\", line 597, in call\n",
      "\n",
      "  File \"/home/alex/.local/lib/python3.12/site-packages/tf_keras/src/layers/normalization/batch_normalization.py\", line 990, in _fused_batch_norm\n",
      "\n",
      "  File \"/home/alex/.local/lib/python3.12/site-packages/tf_keras/src/utils/control_flow_util.py\", line 108, in smart_cond\n",
      "\n",
      "  File \"/home/alex/.local/lib/python3.12/site-packages/tf_keras/src/layers/normalization/batch_normalization.py\", line 979, in _fused_batch_norm_inference\n",
      "\n",
      "No DNN support for stream\n",
      "\t [[{{node model/bn_data/FusedBatchNormV3}}]] [Op:__inference_function_8077]\n",
      "Erreur lors du traitement de data/24_10_09 Soir√©e oeno/IMG_2830.JPG: Graph execution error:\n",
      "\n",
      "Detected at node model/bn_data/FusedBatchNormV3 defined at (most recent call last):\n",
      "  File \"<frozen runpy>\", line 198, in _run_module_as_main\n",
      "\n",
      "  File \"<frozen runpy>\", line 88, in _run_code\n",
      "\n",
      "  File \"/home/alex/.local/lib/python3.12/site-packages/ipykernel_launcher.py\", line 18, in <module>\n",
      "\n",
      "  File \"/home/alex/.local/lib/python3.12/site-packages/traitlets/config/application.py\", line 1075, in launch_instance\n",
      "\n",
      "  File \"/home/alex/.local/lib/python3.12/site-packages/ipykernel/kernelapp.py\", line 739, in start\n",
      "\n",
      "  File \"/home/alex/.local/lib/python3.12/site-packages/tornado/platform/asyncio.py\", line 205, in start\n",
      "\n",
      "  File \"/usr/lib/python3.12/asyncio/base_events.py\", line 641, in run_forever\n",
      "\n",
      "  File \"/usr/lib/python3.12/asyncio/base_events.py\", line 1987, in _run_once\n",
      "\n",
      "  File \"/usr/lib/python3.12/asyncio/events.py\", line 88, in _run\n",
      "\n",
      "  File \"/home/alex/.local/lib/python3.12/site-packages/ipykernel/kernelbase.py\", line 545, in dispatch_queue\n",
      "\n",
      "  File \"/home/alex/.local/lib/python3.12/site-packages/ipykernel/kernelbase.py\", line 534, in process_one\n",
      "\n",
      "  File \"/home/alex/.local/lib/python3.12/site-packages/ipykernel/kernelbase.py\", line 437, in dispatch_shell\n",
      "\n",
      "  File \"/home/alex/.local/lib/python3.12/site-packages/ipykernel/ipkernel.py\", line 362, in execute_request\n",
      "\n",
      "  File \"/home/alex/.local/lib/python3.12/site-packages/ipykernel/kernelbase.py\", line 778, in execute_request\n",
      "\n",
      "  File \"/home/alex/.local/lib/python3.12/site-packages/ipykernel/ipkernel.py\", line 449, in do_execute\n",
      "\n",
      "  File \"/home/alex/.local/lib/python3.12/site-packages/ipykernel/zmqshell.py\", line 549, in run_cell\n",
      "\n",
      "  File \"/home/alex/.local/lib/python3.12/site-packages/IPython/core/interactiveshell.py\", line 3009, in run_cell\n",
      "\n",
      "  File \"/home/alex/.local/lib/python3.12/site-packages/IPython/core/interactiveshell.py\", line 3064, in _run_cell\n",
      "\n",
      "  File \"/home/alex/.local/lib/python3.12/site-packages/IPython/core/async_helpers.py\", line 129, in _pseudo_sync_runner\n",
      "\n",
      "  File \"/home/alex/.local/lib/python3.12/site-packages/IPython/core/interactiveshell.py\", line 3269, in run_cell_async\n",
      "\n",
      "  File \"/home/alex/.local/lib/python3.12/site-packages/IPython/core/interactiveshell.py\", line 3448, in run_ast_nodes\n",
      "\n",
      "  File \"/home/alex/.local/lib/python3.12/site-packages/IPython/core/interactiveshell.py\", line 3508, in run_code\n",
      "\n",
      "  File \"/tmp/ipykernel_82932/3687957463.py\", line 13, in <module>\n",
      "\n",
      "  File \"/tmp/ipykernel_82932/2126864146.py\", line 4, in extract_faces\n",
      "\n",
      "  File \"/home/alex/.local/lib/python3.12/site-packages/deepface/DeepFace.py\", line 549, in extract_faces\n",
      "\n",
      "  File \"/home/alex/.local/lib/python3.12/site-packages/deepface/modules/detection.py\", line 95, in extract_faces\n",
      "\n",
      "  File \"/home/alex/.local/lib/python3.12/site-packages/deepface/modules/detection.py\", line 234, in detect_faces\n",
      "\n",
      "  File \"/home/alex/.local/lib/python3.12/site-packages/deepface/models/face_detection/RetinaFace.py\", line 23, in detect_faces\n",
      "\n",
      "  File \"/home/alex/.local/lib/python3.12/site-packages/retinaface/RetinaFace.py\", line 123, in detect_faces\n",
      "\n",
      "  File \"/home/alex/.local/lib/python3.12/site-packages/tf_keras/src/engine/training.py\", line 553, in error_handler\n",
      "\n",
      "  File \"/home/alex/.local/lib/python3.12/site-packages/tf_keras/src/engine/training.py\", line 558, in error_handler\n",
      "\n",
      "  File \"/home/alex/.local/lib/python3.12/site-packages/tf_keras/src/engine/training.py\", line 588, in __call__\n",
      "\n",
      "  File \"/home/alex/.local/lib/python3.12/site-packages/tf_keras/src/utils/traceback_utils.py\", line 65, in error_handler\n",
      "\n",
      "  File \"/home/alex/.local/lib/python3.12/site-packages/tf_keras/src/engine/base_layer.py\", line 1142, in __call__\n",
      "\n",
      "  File \"/home/alex/.local/lib/python3.12/site-packages/tf_keras/src/utils/traceback_utils.py\", line 96, in error_handler\n",
      "\n",
      "  File \"/home/alex/.local/lib/python3.12/site-packages/tf_keras/src/engine/functional.py\", line 514, in call\n",
      "\n",
      "  File \"/home/alex/.local/lib/python3.12/site-packages/tf_keras/src/engine/functional.py\", line 671, in _run_internal_graph\n",
      "\n",
      "  File \"/home/alex/.local/lib/python3.12/site-packages/tf_keras/src/utils/traceback_utils.py\", line 65, in error_handler\n",
      "\n",
      "  File \"/home/alex/.local/lib/python3.12/site-packages/tf_keras/src/engine/base_layer.py\", line 1142, in __call__\n",
      "\n",
      "  File \"/home/alex/.local/lib/python3.12/site-packages/tf_keras/src/utils/traceback_utils.py\", line 96, in error_handler\n",
      "\n",
      "  File \"/home/alex/.local/lib/python3.12/site-packages/tf_keras/src/layers/normalization/batch_normalization.py\", line 597, in call\n",
      "\n",
      "  File \"/home/alex/.local/lib/python3.12/site-packages/tf_keras/src/layers/normalization/batch_normalization.py\", line 990, in _fused_batch_norm\n",
      "\n",
      "  File \"/home/alex/.local/lib/python3.12/site-packages/tf_keras/src/utils/control_flow_util.py\", line 108, in smart_cond\n",
      "\n",
      "  File \"/home/alex/.local/lib/python3.12/site-packages/tf_keras/src/layers/normalization/batch_normalization.py\", line 979, in _fused_batch_norm_inference\n",
      "\n",
      "No DNN support for stream\n",
      "\t [[{{node model/bn_data/FusedBatchNormV3}}]] [Op:__inference_function_8077]\n"
     ]
    },
    {
     "name": "stderr",
     "output_type": "stream",
     "text": [
      "E0000 00:00:1732727063.913613   83322 cuda_dnn.cc:522] Loaded runtime CuDNN library: 9.1.0 but source was compiled with: 9.3.0.  CuDNN library needs to have matching major version and equal or higher minor version. If using a binary install, upgrade your CuDNN library.  If building from sources, make sure the library loaded at runtime is compatible with the version specified during compile configuration.\n"
     ]
    },
    {
     "name": "stdout",
     "output_type": "stream",
     "text": [
      "Erreur lors du traitement de data/24_10_09 Soir√©e oeno/IMG_2810.JPG: Graph execution error:\n",
      "\n",
      "Detected at node model/bn_data/FusedBatchNormV3 defined at (most recent call last):\n",
      "  File \"<frozen runpy>\", line 198, in _run_module_as_main\n",
      "\n",
      "  File \"<frozen runpy>\", line 88, in _run_code\n",
      "\n",
      "  File \"/home/alex/.local/lib/python3.12/site-packages/ipykernel_launcher.py\", line 18, in <module>\n",
      "\n",
      "  File \"/home/alex/.local/lib/python3.12/site-packages/traitlets/config/application.py\", line 1075, in launch_instance\n",
      "\n",
      "  File \"/home/alex/.local/lib/python3.12/site-packages/ipykernel/kernelapp.py\", line 739, in start\n",
      "\n",
      "  File \"/home/alex/.local/lib/python3.12/site-packages/tornado/platform/asyncio.py\", line 205, in start\n",
      "\n",
      "  File \"/usr/lib/python3.12/asyncio/base_events.py\", line 641, in run_forever\n",
      "\n",
      "  File \"/usr/lib/python3.12/asyncio/base_events.py\", line 1987, in _run_once\n",
      "\n",
      "  File \"/usr/lib/python3.12/asyncio/events.py\", line 88, in _run\n",
      "\n",
      "  File \"/home/alex/.local/lib/python3.12/site-packages/ipykernel/kernelbase.py\", line 545, in dispatch_queue\n",
      "\n",
      "  File \"/home/alex/.local/lib/python3.12/site-packages/ipykernel/kernelbase.py\", line 534, in process_one\n",
      "\n",
      "  File \"/home/alex/.local/lib/python3.12/site-packages/ipykernel/kernelbase.py\", line 437, in dispatch_shell\n",
      "\n",
      "  File \"/home/alex/.local/lib/python3.12/site-packages/ipykernel/ipkernel.py\", line 362, in execute_request\n",
      "\n",
      "  File \"/home/alex/.local/lib/python3.12/site-packages/ipykernel/kernelbase.py\", line 778, in execute_request\n",
      "\n",
      "  File \"/home/alex/.local/lib/python3.12/site-packages/ipykernel/ipkernel.py\", line 449, in do_execute\n",
      "\n",
      "  File \"/home/alex/.local/lib/python3.12/site-packages/ipykernel/zmqshell.py\", line 549, in run_cell\n",
      "\n",
      "  File \"/home/alex/.local/lib/python3.12/site-packages/IPython/core/interactiveshell.py\", line 3009, in run_cell\n",
      "\n",
      "  File \"/home/alex/.local/lib/python3.12/site-packages/IPython/core/interactiveshell.py\", line 3064, in _run_cell\n",
      "\n",
      "  File \"/home/alex/.local/lib/python3.12/site-packages/IPython/core/async_helpers.py\", line 129, in _pseudo_sync_runner\n",
      "\n",
      "  File \"/home/alex/.local/lib/python3.12/site-packages/IPython/core/interactiveshell.py\", line 3269, in run_cell_async\n",
      "\n",
      "  File \"/home/alex/.local/lib/python3.12/site-packages/IPython/core/interactiveshell.py\", line 3448, in run_ast_nodes\n",
      "\n",
      "  File \"/home/alex/.local/lib/python3.12/site-packages/IPython/core/interactiveshell.py\", line 3508, in run_code\n",
      "\n",
      "  File \"/tmp/ipykernel_82932/3687957463.py\", line 13, in <module>\n",
      "\n",
      "  File \"/tmp/ipykernel_82932/2126864146.py\", line 4, in extract_faces\n",
      "\n",
      "  File \"/home/alex/.local/lib/python3.12/site-packages/deepface/DeepFace.py\", line 549, in extract_faces\n",
      "\n",
      "  File \"/home/alex/.local/lib/python3.12/site-packages/deepface/modules/detection.py\", line 95, in extract_faces\n",
      "\n",
      "  File \"/home/alex/.local/lib/python3.12/site-packages/deepface/modules/detection.py\", line 234, in detect_faces\n",
      "\n",
      "  File \"/home/alex/.local/lib/python3.12/site-packages/deepface/models/face_detection/RetinaFace.py\", line 23, in detect_faces\n",
      "\n",
      "  File \"/home/alex/.local/lib/python3.12/site-packages/retinaface/RetinaFace.py\", line 123, in detect_faces\n",
      "\n",
      "  File \"/home/alex/.local/lib/python3.12/site-packages/tf_keras/src/engine/training.py\", line 553, in error_handler\n",
      "\n",
      "  File \"/home/alex/.local/lib/python3.12/site-packages/tf_keras/src/engine/training.py\", line 558, in error_handler\n",
      "\n",
      "  File \"/home/alex/.local/lib/python3.12/site-packages/tf_keras/src/engine/training.py\", line 588, in __call__\n",
      "\n",
      "  File \"/home/alex/.local/lib/python3.12/site-packages/tf_keras/src/utils/traceback_utils.py\", line 65, in error_handler\n",
      "\n",
      "  File \"/home/alex/.local/lib/python3.12/site-packages/tf_keras/src/engine/base_layer.py\", line 1142, in __call__\n",
      "\n",
      "  File \"/home/alex/.local/lib/python3.12/site-packages/tf_keras/src/utils/traceback_utils.py\", line 96, in error_handler\n",
      "\n",
      "  File \"/home/alex/.local/lib/python3.12/site-packages/tf_keras/src/engine/functional.py\", line 514, in call\n",
      "\n",
      "  File \"/home/alex/.local/lib/python3.12/site-packages/tf_keras/src/engine/functional.py\", line 671, in _run_internal_graph\n",
      "\n",
      "  File \"/home/alex/.local/lib/python3.12/site-packages/tf_keras/src/utils/traceback_utils.py\", line 65, in error_handler\n",
      "\n",
      "  File \"/home/alex/.local/lib/python3.12/site-packages/tf_keras/src/engine/base_layer.py\", line 1142, in __call__\n",
      "\n",
      "  File \"/home/alex/.local/lib/python3.12/site-packages/tf_keras/src/utils/traceback_utils.py\", line 96, in error_handler\n",
      "\n",
      "  File \"/home/alex/.local/lib/python3.12/site-packages/tf_keras/src/layers/normalization/batch_normalization.py\", line 597, in call\n",
      "\n",
      "  File \"/home/alex/.local/lib/python3.12/site-packages/tf_keras/src/layers/normalization/batch_normalization.py\", line 990, in _fused_batch_norm\n",
      "\n",
      "  File \"/home/alex/.local/lib/python3.12/site-packages/tf_keras/src/utils/control_flow_util.py\", line 108, in smart_cond\n",
      "\n",
      "  File \"/home/alex/.local/lib/python3.12/site-packages/tf_keras/src/layers/normalization/batch_normalization.py\", line 979, in _fused_batch_norm_inference\n",
      "\n",
      "No DNN support for stream\n",
      "\t [[{{node model/bn_data/FusedBatchNormV3}}]] [Op:__inference_function_8077]\n"
     ]
    },
    {
     "name": "stderr",
     "output_type": "stream",
     "text": [
      "E0000 00:00:1732727064.122578   83333 cuda_dnn.cc:522] Loaded runtime CuDNN library: 9.1.0 but source was compiled with: 9.3.0.  CuDNN library needs to have matching major version and equal or higher minor version. If using a binary install, upgrade your CuDNN library.  If building from sources, make sure the library loaded at runtime is compatible with the version specified during compile configuration.\n",
      "E0000 00:00:1732727064.319520   83322 cuda_dnn.cc:522] Loaded runtime CuDNN library: 9.1.0 but source was compiled with: 9.3.0.  CuDNN library needs to have matching major version and equal or higher minor version. If using a binary install, upgrade your CuDNN library.  If building from sources, make sure the library loaded at runtime is compatible with the version specified during compile configuration.\n"
     ]
    },
    {
     "name": "stdout",
     "output_type": "stream",
     "text": [
      "Erreur lors du traitement de data/24_10_09 Soir√©e oeno/IMG_2872.JPG: Graph execution error:\n",
      "\n",
      "Detected at node model/bn_data/FusedBatchNormV3 defined at (most recent call last):\n",
      "  File \"<frozen runpy>\", line 198, in _run_module_as_main\n",
      "\n",
      "  File \"<frozen runpy>\", line 88, in _run_code\n",
      "\n",
      "  File \"/home/alex/.local/lib/python3.12/site-packages/ipykernel_launcher.py\", line 18, in <module>\n",
      "\n",
      "  File \"/home/alex/.local/lib/python3.12/site-packages/traitlets/config/application.py\", line 1075, in launch_instance\n",
      "\n",
      "  File \"/home/alex/.local/lib/python3.12/site-packages/ipykernel/kernelapp.py\", line 739, in start\n",
      "\n",
      "  File \"/home/alex/.local/lib/python3.12/site-packages/tornado/platform/asyncio.py\", line 205, in start\n",
      "\n",
      "  File \"/usr/lib/python3.12/asyncio/base_events.py\", line 641, in run_forever\n",
      "\n",
      "  File \"/usr/lib/python3.12/asyncio/base_events.py\", line 1987, in _run_once\n",
      "\n",
      "  File \"/usr/lib/python3.12/asyncio/events.py\", line 88, in _run\n",
      "\n",
      "  File \"/home/alex/.local/lib/python3.12/site-packages/ipykernel/kernelbase.py\", line 545, in dispatch_queue\n",
      "\n",
      "  File \"/home/alex/.local/lib/python3.12/site-packages/ipykernel/kernelbase.py\", line 534, in process_one\n",
      "\n",
      "  File \"/home/alex/.local/lib/python3.12/site-packages/ipykernel/kernelbase.py\", line 437, in dispatch_shell\n",
      "\n",
      "  File \"/home/alex/.local/lib/python3.12/site-packages/ipykernel/ipkernel.py\", line 362, in execute_request\n",
      "\n",
      "  File \"/home/alex/.local/lib/python3.12/site-packages/ipykernel/kernelbase.py\", line 778, in execute_request\n",
      "\n",
      "  File \"/home/alex/.local/lib/python3.12/site-packages/ipykernel/ipkernel.py\", line 449, in do_execute\n",
      "\n",
      "  File \"/home/alex/.local/lib/python3.12/site-packages/ipykernel/zmqshell.py\", line 549, in run_cell\n",
      "\n",
      "  File \"/home/alex/.local/lib/python3.12/site-packages/IPython/core/interactiveshell.py\", line 3009, in run_cell\n",
      "\n",
      "  File \"/home/alex/.local/lib/python3.12/site-packages/IPython/core/interactiveshell.py\", line 3064, in _run_cell\n",
      "\n",
      "  File \"/home/alex/.local/lib/python3.12/site-packages/IPython/core/async_helpers.py\", line 129, in _pseudo_sync_runner\n",
      "\n",
      "  File \"/home/alex/.local/lib/python3.12/site-packages/IPython/core/interactiveshell.py\", line 3269, in run_cell_async\n",
      "\n",
      "  File \"/home/alex/.local/lib/python3.12/site-packages/IPython/core/interactiveshell.py\", line 3448, in run_ast_nodes\n",
      "\n",
      "  File \"/home/alex/.local/lib/python3.12/site-packages/IPython/core/interactiveshell.py\", line 3508, in run_code\n",
      "\n",
      "  File \"/tmp/ipykernel_82932/3687957463.py\", line 13, in <module>\n",
      "\n",
      "  File \"/tmp/ipykernel_82932/2126864146.py\", line 4, in extract_faces\n",
      "\n",
      "  File \"/home/alex/.local/lib/python3.12/site-packages/deepface/DeepFace.py\", line 549, in extract_faces\n",
      "\n",
      "  File \"/home/alex/.local/lib/python3.12/site-packages/deepface/modules/detection.py\", line 95, in extract_faces\n",
      "\n",
      "  File \"/home/alex/.local/lib/python3.12/site-packages/deepface/modules/detection.py\", line 234, in detect_faces\n",
      "\n",
      "  File \"/home/alex/.local/lib/python3.12/site-packages/deepface/models/face_detection/RetinaFace.py\", line 23, in detect_faces\n",
      "\n",
      "  File \"/home/alex/.local/lib/python3.12/site-packages/retinaface/RetinaFace.py\", line 123, in detect_faces\n",
      "\n",
      "  File \"/home/alex/.local/lib/python3.12/site-packages/tf_keras/src/engine/training.py\", line 553, in error_handler\n",
      "\n",
      "  File \"/home/alex/.local/lib/python3.12/site-packages/tf_keras/src/engine/training.py\", line 558, in error_handler\n",
      "\n",
      "  File \"/home/alex/.local/lib/python3.12/site-packages/tf_keras/src/engine/training.py\", line 588, in __call__\n",
      "\n",
      "  File \"/home/alex/.local/lib/python3.12/site-packages/tf_keras/src/utils/traceback_utils.py\", line 65, in error_handler\n",
      "\n",
      "  File \"/home/alex/.local/lib/python3.12/site-packages/tf_keras/src/engine/base_layer.py\", line 1142, in __call__\n",
      "\n",
      "  File \"/home/alex/.local/lib/python3.12/site-packages/tf_keras/src/utils/traceback_utils.py\", line 96, in error_handler\n",
      "\n",
      "  File \"/home/alex/.local/lib/python3.12/site-packages/tf_keras/src/engine/functional.py\", line 514, in call\n",
      "\n",
      "  File \"/home/alex/.local/lib/python3.12/site-packages/tf_keras/src/engine/functional.py\", line 671, in _run_internal_graph\n",
      "\n",
      "  File \"/home/alex/.local/lib/python3.12/site-packages/tf_keras/src/utils/traceback_utils.py\", line 65, in error_handler\n",
      "\n",
      "  File \"/home/alex/.local/lib/python3.12/site-packages/tf_keras/src/engine/base_layer.py\", line 1142, in __call__\n",
      "\n",
      "  File \"/home/alex/.local/lib/python3.12/site-packages/tf_keras/src/utils/traceback_utils.py\", line 96, in error_handler\n",
      "\n",
      "  File \"/home/alex/.local/lib/python3.12/site-packages/tf_keras/src/layers/normalization/batch_normalization.py\", line 597, in call\n",
      "\n",
      "  File \"/home/alex/.local/lib/python3.12/site-packages/tf_keras/src/layers/normalization/batch_normalization.py\", line 990, in _fused_batch_norm\n",
      "\n",
      "  File \"/home/alex/.local/lib/python3.12/site-packages/tf_keras/src/utils/control_flow_util.py\", line 108, in smart_cond\n",
      "\n",
      "  File \"/home/alex/.local/lib/python3.12/site-packages/tf_keras/src/layers/normalization/batch_normalization.py\", line 979, in _fused_batch_norm_inference\n",
      "\n",
      "No DNN support for stream\n",
      "\t [[{{node model/bn_data/FusedBatchNormV3}}]] [Op:__inference_function_8077]\n",
      "Erreur lors du traitement de data/24_10_09 Soir√©e oeno/IMG_2765.JPG: Graph execution error:\n",
      "\n",
      "Detected at node model/bn_data/FusedBatchNormV3 defined at (most recent call last):\n",
      "  File \"<frozen runpy>\", line 198, in _run_module_as_main\n",
      "\n",
      "  File \"<frozen runpy>\", line 88, in _run_code\n",
      "\n",
      "  File \"/home/alex/.local/lib/python3.12/site-packages/ipykernel_launcher.py\", line 18, in <module>\n",
      "\n",
      "  File \"/home/alex/.local/lib/python3.12/site-packages/traitlets/config/application.py\", line 1075, in launch_instance\n",
      "\n",
      "  File \"/home/alex/.local/lib/python3.12/site-packages/ipykernel/kernelapp.py\", line 739, in start\n",
      "\n",
      "  File \"/home/alex/.local/lib/python3.12/site-packages/tornado/platform/asyncio.py\", line 205, in start\n",
      "\n",
      "  File \"/usr/lib/python3.12/asyncio/base_events.py\", line 641, in run_forever\n",
      "\n",
      "  File \"/usr/lib/python3.12/asyncio/base_events.py\", line 1987, in _run_once\n",
      "\n",
      "  File \"/usr/lib/python3.12/asyncio/events.py\", line 88, in _run\n",
      "\n",
      "  File \"/home/alex/.local/lib/python3.12/site-packages/ipykernel/kernelbase.py\", line 545, in dispatch_queue\n",
      "\n",
      "  File \"/home/alex/.local/lib/python3.12/site-packages/ipykernel/kernelbase.py\", line 534, in process_one\n",
      "\n",
      "  File \"/home/alex/.local/lib/python3.12/site-packages/ipykernel/kernelbase.py\", line 437, in dispatch_shell\n",
      "\n",
      "  File \"/home/alex/.local/lib/python3.12/site-packages/ipykernel/ipkernel.py\", line 362, in execute_request\n",
      "\n",
      "  File \"/home/alex/.local/lib/python3.12/site-packages/ipykernel/kernelbase.py\", line 778, in execute_request\n",
      "\n",
      "  File \"/home/alex/.local/lib/python3.12/site-packages/ipykernel/ipkernel.py\", line 449, in do_execute\n",
      "\n",
      "  File \"/home/alex/.local/lib/python3.12/site-packages/ipykernel/zmqshell.py\", line 549, in run_cell\n",
      "\n",
      "  File \"/home/alex/.local/lib/python3.12/site-packages/IPython/core/interactiveshell.py\", line 3009, in run_cell\n",
      "\n",
      "  File \"/home/alex/.local/lib/python3.12/site-packages/IPython/core/interactiveshell.py\", line 3064, in _run_cell\n",
      "\n",
      "  File \"/home/alex/.local/lib/python3.12/site-packages/IPython/core/async_helpers.py\", line 129, in _pseudo_sync_runner\n",
      "\n",
      "  File \"/home/alex/.local/lib/python3.12/site-packages/IPython/core/interactiveshell.py\", line 3269, in run_cell_async\n",
      "\n",
      "  File \"/home/alex/.local/lib/python3.12/site-packages/IPython/core/interactiveshell.py\", line 3448, in run_ast_nodes\n",
      "\n",
      "  File \"/home/alex/.local/lib/python3.12/site-packages/IPython/core/interactiveshell.py\", line 3508, in run_code\n",
      "\n",
      "  File \"/tmp/ipykernel_82932/3687957463.py\", line 13, in <module>\n",
      "\n",
      "  File \"/tmp/ipykernel_82932/2126864146.py\", line 4, in extract_faces\n",
      "\n",
      "  File \"/home/alex/.local/lib/python3.12/site-packages/deepface/DeepFace.py\", line 549, in extract_faces\n",
      "\n",
      "  File \"/home/alex/.local/lib/python3.12/site-packages/deepface/modules/detection.py\", line 95, in extract_faces\n",
      "\n",
      "  File \"/home/alex/.local/lib/python3.12/site-packages/deepface/modules/detection.py\", line 234, in detect_faces\n",
      "\n",
      "  File \"/home/alex/.local/lib/python3.12/site-packages/deepface/models/face_detection/RetinaFace.py\", line 23, in detect_faces\n",
      "\n",
      "  File \"/home/alex/.local/lib/python3.12/site-packages/retinaface/RetinaFace.py\", line 123, in detect_faces\n",
      "\n",
      "  File \"/home/alex/.local/lib/python3.12/site-packages/tf_keras/src/engine/training.py\", line 553, in error_handler\n",
      "\n",
      "  File \"/home/alex/.local/lib/python3.12/site-packages/tf_keras/src/engine/training.py\", line 558, in error_handler\n",
      "\n",
      "  File \"/home/alex/.local/lib/python3.12/site-packages/tf_keras/src/engine/training.py\", line 588, in __call__\n",
      "\n",
      "  File \"/home/alex/.local/lib/python3.12/site-packages/tf_keras/src/utils/traceback_utils.py\", line 65, in error_handler\n",
      "\n",
      "  File \"/home/alex/.local/lib/python3.12/site-packages/tf_keras/src/engine/base_layer.py\", line 1142, in __call__\n",
      "\n",
      "  File \"/home/alex/.local/lib/python3.12/site-packages/tf_keras/src/utils/traceback_utils.py\", line 96, in error_handler\n",
      "\n",
      "  File \"/home/alex/.local/lib/python3.12/site-packages/tf_keras/src/engine/functional.py\", line 514, in call\n",
      "\n",
      "  File \"/home/alex/.local/lib/python3.12/site-packages/tf_keras/src/engine/functional.py\", line 671, in _run_internal_graph\n",
      "\n",
      "  File \"/home/alex/.local/lib/python3.12/site-packages/tf_keras/src/utils/traceback_utils.py\", line 65, in error_handler\n",
      "\n",
      "  File \"/home/alex/.local/lib/python3.12/site-packages/tf_keras/src/engine/base_layer.py\", line 1142, in __call__\n",
      "\n",
      "  File \"/home/alex/.local/lib/python3.12/site-packages/tf_keras/src/utils/traceback_utils.py\", line 96, in error_handler\n",
      "\n",
      "  File \"/home/alex/.local/lib/python3.12/site-packages/tf_keras/src/layers/normalization/batch_normalization.py\", line 597, in call\n",
      "\n",
      "  File \"/home/alex/.local/lib/python3.12/site-packages/tf_keras/src/layers/normalization/batch_normalization.py\", line 990, in _fused_batch_norm\n",
      "\n",
      "  File \"/home/alex/.local/lib/python3.12/site-packages/tf_keras/src/utils/control_flow_util.py\", line 108, in smart_cond\n",
      "\n",
      "  File \"/home/alex/.local/lib/python3.12/site-packages/tf_keras/src/layers/normalization/batch_normalization.py\", line 979, in _fused_batch_norm_inference\n",
      "\n",
      "No DNN support for stream\n",
      "\t [[{{node model/bn_data/FusedBatchNormV3}}]] [Op:__inference_function_8077]\n"
     ]
    },
    {
     "name": "stderr",
     "output_type": "stream",
     "text": [
      "E0000 00:00:1732727064.527169   83333 cuda_dnn.cc:522] Loaded runtime CuDNN library: 9.1.0 but source was compiled with: 9.3.0.  CuDNN library needs to have matching major version and equal or higher minor version. If using a binary install, upgrade your CuDNN library.  If building from sources, make sure the library loaded at runtime is compatible with the version specified during compile configuration.\n",
      "E0000 00:00:1732727064.706205   83322 cuda_dnn.cc:522] Loaded runtime CuDNN library: 9.1.0 but source was compiled with: 9.3.0.  CuDNN library needs to have matching major version and equal or higher minor version. If using a binary install, upgrade your CuDNN library.  If building from sources, make sure the library loaded at runtime is compatible with the version specified during compile configuration.\n"
     ]
    },
    {
     "name": "stdout",
     "output_type": "stream",
     "text": [
      "Erreur lors du traitement de data/24_10_09 Soir√©e oeno/IMG_2784.JPG: Graph execution error:\n",
      "\n",
      "Detected at node model/bn_data/FusedBatchNormV3 defined at (most recent call last):\n",
      "  File \"<frozen runpy>\", line 198, in _run_module_as_main\n",
      "\n",
      "  File \"<frozen runpy>\", line 88, in _run_code\n",
      "\n",
      "  File \"/home/alex/.local/lib/python3.12/site-packages/ipykernel_launcher.py\", line 18, in <module>\n",
      "\n",
      "  File \"/home/alex/.local/lib/python3.12/site-packages/traitlets/config/application.py\", line 1075, in launch_instance\n",
      "\n",
      "  File \"/home/alex/.local/lib/python3.12/site-packages/ipykernel/kernelapp.py\", line 739, in start\n",
      "\n",
      "  File \"/home/alex/.local/lib/python3.12/site-packages/tornado/platform/asyncio.py\", line 205, in start\n",
      "\n",
      "  File \"/usr/lib/python3.12/asyncio/base_events.py\", line 641, in run_forever\n",
      "\n",
      "  File \"/usr/lib/python3.12/asyncio/base_events.py\", line 1987, in _run_once\n",
      "\n",
      "  File \"/usr/lib/python3.12/asyncio/events.py\", line 88, in _run\n",
      "\n",
      "  File \"/home/alex/.local/lib/python3.12/site-packages/ipykernel/kernelbase.py\", line 545, in dispatch_queue\n",
      "\n",
      "  File \"/home/alex/.local/lib/python3.12/site-packages/ipykernel/kernelbase.py\", line 534, in process_one\n",
      "\n",
      "  File \"/home/alex/.local/lib/python3.12/site-packages/ipykernel/kernelbase.py\", line 437, in dispatch_shell\n",
      "\n",
      "  File \"/home/alex/.local/lib/python3.12/site-packages/ipykernel/ipkernel.py\", line 362, in execute_request\n",
      "\n",
      "  File \"/home/alex/.local/lib/python3.12/site-packages/ipykernel/kernelbase.py\", line 778, in execute_request\n",
      "\n",
      "  File \"/home/alex/.local/lib/python3.12/site-packages/ipykernel/ipkernel.py\", line 449, in do_execute\n",
      "\n",
      "  File \"/home/alex/.local/lib/python3.12/site-packages/ipykernel/zmqshell.py\", line 549, in run_cell\n",
      "\n",
      "  File \"/home/alex/.local/lib/python3.12/site-packages/IPython/core/interactiveshell.py\", line 3009, in run_cell\n",
      "\n",
      "  File \"/home/alex/.local/lib/python3.12/site-packages/IPython/core/interactiveshell.py\", line 3064, in _run_cell\n",
      "\n",
      "  File \"/home/alex/.local/lib/python3.12/site-packages/IPython/core/async_helpers.py\", line 129, in _pseudo_sync_runner\n",
      "\n",
      "  File \"/home/alex/.local/lib/python3.12/site-packages/IPython/core/interactiveshell.py\", line 3269, in run_cell_async\n",
      "\n",
      "  File \"/home/alex/.local/lib/python3.12/site-packages/IPython/core/interactiveshell.py\", line 3448, in run_ast_nodes\n",
      "\n",
      "  File \"/home/alex/.local/lib/python3.12/site-packages/IPython/core/interactiveshell.py\", line 3508, in run_code\n",
      "\n",
      "  File \"/tmp/ipykernel_82932/3687957463.py\", line 13, in <module>\n",
      "\n",
      "  File \"/tmp/ipykernel_82932/2126864146.py\", line 4, in extract_faces\n",
      "\n",
      "  File \"/home/alex/.local/lib/python3.12/site-packages/deepface/DeepFace.py\", line 549, in extract_faces\n",
      "\n",
      "  File \"/home/alex/.local/lib/python3.12/site-packages/deepface/modules/detection.py\", line 95, in extract_faces\n",
      "\n",
      "  File \"/home/alex/.local/lib/python3.12/site-packages/deepface/modules/detection.py\", line 234, in detect_faces\n",
      "\n",
      "  File \"/home/alex/.local/lib/python3.12/site-packages/deepface/models/face_detection/RetinaFace.py\", line 23, in detect_faces\n",
      "\n",
      "  File \"/home/alex/.local/lib/python3.12/site-packages/retinaface/RetinaFace.py\", line 123, in detect_faces\n",
      "\n",
      "  File \"/home/alex/.local/lib/python3.12/site-packages/tf_keras/src/engine/training.py\", line 553, in error_handler\n",
      "\n",
      "  File \"/home/alex/.local/lib/python3.12/site-packages/tf_keras/src/engine/training.py\", line 558, in error_handler\n",
      "\n",
      "  File \"/home/alex/.local/lib/python3.12/site-packages/tf_keras/src/engine/training.py\", line 588, in __call__\n",
      "\n",
      "  File \"/home/alex/.local/lib/python3.12/site-packages/tf_keras/src/utils/traceback_utils.py\", line 65, in error_handler\n",
      "\n",
      "  File \"/home/alex/.local/lib/python3.12/site-packages/tf_keras/src/engine/base_layer.py\", line 1142, in __call__\n",
      "\n",
      "  File \"/home/alex/.local/lib/python3.12/site-packages/tf_keras/src/utils/traceback_utils.py\", line 96, in error_handler\n",
      "\n",
      "  File \"/home/alex/.local/lib/python3.12/site-packages/tf_keras/src/engine/functional.py\", line 514, in call\n",
      "\n",
      "  File \"/home/alex/.local/lib/python3.12/site-packages/tf_keras/src/engine/functional.py\", line 671, in _run_internal_graph\n",
      "\n",
      "  File \"/home/alex/.local/lib/python3.12/site-packages/tf_keras/src/utils/traceback_utils.py\", line 65, in error_handler\n",
      "\n",
      "  File \"/home/alex/.local/lib/python3.12/site-packages/tf_keras/src/engine/base_layer.py\", line 1142, in __call__\n",
      "\n",
      "  File \"/home/alex/.local/lib/python3.12/site-packages/tf_keras/src/utils/traceback_utils.py\", line 96, in error_handler\n",
      "\n",
      "  File \"/home/alex/.local/lib/python3.12/site-packages/tf_keras/src/layers/normalization/batch_normalization.py\", line 597, in call\n",
      "\n",
      "  File \"/home/alex/.local/lib/python3.12/site-packages/tf_keras/src/layers/normalization/batch_normalization.py\", line 990, in _fused_batch_norm\n",
      "\n",
      "  File \"/home/alex/.local/lib/python3.12/site-packages/tf_keras/src/utils/control_flow_util.py\", line 108, in smart_cond\n",
      "\n",
      "  File \"/home/alex/.local/lib/python3.12/site-packages/tf_keras/src/layers/normalization/batch_normalization.py\", line 979, in _fused_batch_norm_inference\n",
      "\n",
      "No DNN support for stream\n",
      "\t [[{{node model/bn_data/FusedBatchNormV3}}]] [Op:__inference_function_8077]\n",
      "Erreur lors du traitement de data/24_10_09 Soir√©e oeno/IMG_2732.JPG: Graph execution error:\n",
      "\n",
      "Detected at node model/bn_data/FusedBatchNormV3 defined at (most recent call last):\n",
      "  File \"<frozen runpy>\", line 198, in _run_module_as_main\n",
      "\n",
      "  File \"<frozen runpy>\", line 88, in _run_code\n",
      "\n",
      "  File \"/home/alex/.local/lib/python3.12/site-packages/ipykernel_launcher.py\", line 18, in <module>\n",
      "\n",
      "  File \"/home/alex/.local/lib/python3.12/site-packages/traitlets/config/application.py\", line 1075, in launch_instance\n",
      "\n",
      "  File \"/home/alex/.local/lib/python3.12/site-packages/ipykernel/kernelapp.py\", line 739, in start\n",
      "\n",
      "  File \"/home/alex/.local/lib/python3.12/site-packages/tornado/platform/asyncio.py\", line 205, in start\n",
      "\n",
      "  File \"/usr/lib/python3.12/asyncio/base_events.py\", line 641, in run_forever\n",
      "\n",
      "  File \"/usr/lib/python3.12/asyncio/base_events.py\", line 1987, in _run_once\n",
      "\n",
      "  File \"/usr/lib/python3.12/asyncio/events.py\", line 88, in _run\n",
      "\n",
      "  File \"/home/alex/.local/lib/python3.12/site-packages/ipykernel/kernelbase.py\", line 545, in dispatch_queue\n",
      "\n",
      "  File \"/home/alex/.local/lib/python3.12/site-packages/ipykernel/kernelbase.py\", line 534, in process_one\n",
      "\n",
      "  File \"/home/alex/.local/lib/python3.12/site-packages/ipykernel/kernelbase.py\", line 437, in dispatch_shell\n",
      "\n",
      "  File \"/home/alex/.local/lib/python3.12/site-packages/ipykernel/ipkernel.py\", line 362, in execute_request\n",
      "\n",
      "  File \"/home/alex/.local/lib/python3.12/site-packages/ipykernel/kernelbase.py\", line 778, in execute_request\n",
      "\n",
      "  File \"/home/alex/.local/lib/python3.12/site-packages/ipykernel/ipkernel.py\", line 449, in do_execute\n",
      "\n",
      "  File \"/home/alex/.local/lib/python3.12/site-packages/ipykernel/zmqshell.py\", line 549, in run_cell\n",
      "\n",
      "  File \"/home/alex/.local/lib/python3.12/site-packages/IPython/core/interactiveshell.py\", line 3009, in run_cell\n",
      "\n",
      "  File \"/home/alex/.local/lib/python3.12/site-packages/IPython/core/interactiveshell.py\", line 3064, in _run_cell\n",
      "\n",
      "  File \"/home/alex/.local/lib/python3.12/site-packages/IPython/core/async_helpers.py\", line 129, in _pseudo_sync_runner\n",
      "\n",
      "  File \"/home/alex/.local/lib/python3.12/site-packages/IPython/core/interactiveshell.py\", line 3269, in run_cell_async\n",
      "\n",
      "  File \"/home/alex/.local/lib/python3.12/site-packages/IPython/core/interactiveshell.py\", line 3448, in run_ast_nodes\n",
      "\n",
      "  File \"/home/alex/.local/lib/python3.12/site-packages/IPython/core/interactiveshell.py\", line 3508, in run_code\n",
      "\n",
      "  File \"/tmp/ipykernel_82932/3687957463.py\", line 13, in <module>\n",
      "\n",
      "  File \"/tmp/ipykernel_82932/2126864146.py\", line 4, in extract_faces\n",
      "\n",
      "  File \"/home/alex/.local/lib/python3.12/site-packages/deepface/DeepFace.py\", line 549, in extract_faces\n",
      "\n",
      "  File \"/home/alex/.local/lib/python3.12/site-packages/deepface/modules/detection.py\", line 95, in extract_faces\n",
      "\n",
      "  File \"/home/alex/.local/lib/python3.12/site-packages/deepface/modules/detection.py\", line 234, in detect_faces\n",
      "\n",
      "  File \"/home/alex/.local/lib/python3.12/site-packages/deepface/models/face_detection/RetinaFace.py\", line 23, in detect_faces\n",
      "\n",
      "  File \"/home/alex/.local/lib/python3.12/site-packages/retinaface/RetinaFace.py\", line 123, in detect_faces\n",
      "\n",
      "  File \"/home/alex/.local/lib/python3.12/site-packages/tf_keras/src/engine/training.py\", line 553, in error_handler\n",
      "\n",
      "  File \"/home/alex/.local/lib/python3.12/site-packages/tf_keras/src/engine/training.py\", line 558, in error_handler\n",
      "\n",
      "  File \"/home/alex/.local/lib/python3.12/site-packages/tf_keras/src/engine/training.py\", line 588, in __call__\n",
      "\n",
      "  File \"/home/alex/.local/lib/python3.12/site-packages/tf_keras/src/utils/traceback_utils.py\", line 65, in error_handler\n",
      "\n",
      "  File \"/home/alex/.local/lib/python3.12/site-packages/tf_keras/src/engine/base_layer.py\", line 1142, in __call__\n",
      "\n",
      "  File \"/home/alex/.local/lib/python3.12/site-packages/tf_keras/src/utils/traceback_utils.py\", line 96, in error_handler\n",
      "\n",
      "  File \"/home/alex/.local/lib/python3.12/site-packages/tf_keras/src/engine/functional.py\", line 514, in call\n",
      "\n",
      "  File \"/home/alex/.local/lib/python3.12/site-packages/tf_keras/src/engine/functional.py\", line 671, in _run_internal_graph\n",
      "\n",
      "  File \"/home/alex/.local/lib/python3.12/site-packages/tf_keras/src/utils/traceback_utils.py\", line 65, in error_handler\n",
      "\n",
      "  File \"/home/alex/.local/lib/python3.12/site-packages/tf_keras/src/engine/base_layer.py\", line 1142, in __call__\n",
      "\n",
      "  File \"/home/alex/.local/lib/python3.12/site-packages/tf_keras/src/utils/traceback_utils.py\", line 96, in error_handler\n",
      "\n",
      "  File \"/home/alex/.local/lib/python3.12/site-packages/tf_keras/src/layers/normalization/batch_normalization.py\", line 597, in call\n",
      "\n",
      "  File \"/home/alex/.local/lib/python3.12/site-packages/tf_keras/src/layers/normalization/batch_normalization.py\", line 990, in _fused_batch_norm\n",
      "\n",
      "  File \"/home/alex/.local/lib/python3.12/site-packages/tf_keras/src/utils/control_flow_util.py\", line 108, in smart_cond\n",
      "\n",
      "  File \"/home/alex/.local/lib/python3.12/site-packages/tf_keras/src/layers/normalization/batch_normalization.py\", line 979, in _fused_batch_norm_inference\n",
      "\n",
      "No DNN support for stream\n",
      "\t [[{{node model/bn_data/FusedBatchNormV3}}]] [Op:__inference_function_8077]\n"
     ]
    },
    {
     "name": "stderr",
     "output_type": "stream",
     "text": [
      "E0000 00:00:1732727064.913383   83333 cuda_dnn.cc:522] Loaded runtime CuDNN library: 9.1.0 but source was compiled with: 9.3.0.  CuDNN library needs to have matching major version and equal or higher minor version. If using a binary install, upgrade your CuDNN library.  If building from sources, make sure the library loaded at runtime is compatible with the version specified during compile configuration.\n",
      "E0000 00:00:1732727065.108752   83333 cuda_dnn.cc:522] Loaded runtime CuDNN library: 9.1.0 but source was compiled with: 9.3.0.  CuDNN library needs to have matching major version and equal or higher minor version. If using a binary install, upgrade your CuDNN library.  If building from sources, make sure the library loaded at runtime is compatible with the version specified during compile configuration.\n"
     ]
    },
    {
     "name": "stdout",
     "output_type": "stream",
     "text": [
      "Erreur lors du traitement de data/24_10_09 Soir√©e oeno/IMG_2864.JPG: Graph execution error:\n",
      "\n",
      "Detected at node model/bn_data/FusedBatchNormV3 defined at (most recent call last):\n",
      "  File \"<frozen runpy>\", line 198, in _run_module_as_main\n",
      "\n",
      "  File \"<frozen runpy>\", line 88, in _run_code\n",
      "\n",
      "  File \"/home/alex/.local/lib/python3.12/site-packages/ipykernel_launcher.py\", line 18, in <module>\n",
      "\n",
      "  File \"/home/alex/.local/lib/python3.12/site-packages/traitlets/config/application.py\", line 1075, in launch_instance\n",
      "\n",
      "  File \"/home/alex/.local/lib/python3.12/site-packages/ipykernel/kernelapp.py\", line 739, in start\n",
      "\n",
      "  File \"/home/alex/.local/lib/python3.12/site-packages/tornado/platform/asyncio.py\", line 205, in start\n",
      "\n",
      "  File \"/usr/lib/python3.12/asyncio/base_events.py\", line 641, in run_forever\n",
      "\n",
      "  File \"/usr/lib/python3.12/asyncio/base_events.py\", line 1987, in _run_once\n",
      "\n",
      "  File \"/usr/lib/python3.12/asyncio/events.py\", line 88, in _run\n",
      "\n",
      "  File \"/home/alex/.local/lib/python3.12/site-packages/ipykernel/kernelbase.py\", line 545, in dispatch_queue\n",
      "\n",
      "  File \"/home/alex/.local/lib/python3.12/site-packages/ipykernel/kernelbase.py\", line 534, in process_one\n",
      "\n",
      "  File \"/home/alex/.local/lib/python3.12/site-packages/ipykernel/kernelbase.py\", line 437, in dispatch_shell\n",
      "\n",
      "  File \"/home/alex/.local/lib/python3.12/site-packages/ipykernel/ipkernel.py\", line 362, in execute_request\n",
      "\n",
      "  File \"/home/alex/.local/lib/python3.12/site-packages/ipykernel/kernelbase.py\", line 778, in execute_request\n",
      "\n",
      "  File \"/home/alex/.local/lib/python3.12/site-packages/ipykernel/ipkernel.py\", line 449, in do_execute\n",
      "\n",
      "  File \"/home/alex/.local/lib/python3.12/site-packages/ipykernel/zmqshell.py\", line 549, in run_cell\n",
      "\n",
      "  File \"/home/alex/.local/lib/python3.12/site-packages/IPython/core/interactiveshell.py\", line 3009, in run_cell\n",
      "\n",
      "  File \"/home/alex/.local/lib/python3.12/site-packages/IPython/core/interactiveshell.py\", line 3064, in _run_cell\n",
      "\n",
      "  File \"/home/alex/.local/lib/python3.12/site-packages/IPython/core/async_helpers.py\", line 129, in _pseudo_sync_runner\n",
      "\n",
      "  File \"/home/alex/.local/lib/python3.12/site-packages/IPython/core/interactiveshell.py\", line 3269, in run_cell_async\n",
      "\n",
      "  File \"/home/alex/.local/lib/python3.12/site-packages/IPython/core/interactiveshell.py\", line 3448, in run_ast_nodes\n",
      "\n",
      "  File \"/home/alex/.local/lib/python3.12/site-packages/IPython/core/interactiveshell.py\", line 3508, in run_code\n",
      "\n",
      "  File \"/tmp/ipykernel_82932/3687957463.py\", line 13, in <module>\n",
      "\n",
      "  File \"/tmp/ipykernel_82932/2126864146.py\", line 4, in extract_faces\n",
      "\n",
      "  File \"/home/alex/.local/lib/python3.12/site-packages/deepface/DeepFace.py\", line 549, in extract_faces\n",
      "\n",
      "  File \"/home/alex/.local/lib/python3.12/site-packages/deepface/modules/detection.py\", line 95, in extract_faces\n",
      "\n",
      "  File \"/home/alex/.local/lib/python3.12/site-packages/deepface/modules/detection.py\", line 234, in detect_faces\n",
      "\n",
      "  File \"/home/alex/.local/lib/python3.12/site-packages/deepface/models/face_detection/RetinaFace.py\", line 23, in detect_faces\n",
      "\n",
      "  File \"/home/alex/.local/lib/python3.12/site-packages/retinaface/RetinaFace.py\", line 123, in detect_faces\n",
      "\n",
      "  File \"/home/alex/.local/lib/python3.12/site-packages/tf_keras/src/engine/training.py\", line 553, in error_handler\n",
      "\n",
      "  File \"/home/alex/.local/lib/python3.12/site-packages/tf_keras/src/engine/training.py\", line 558, in error_handler\n",
      "\n",
      "  File \"/home/alex/.local/lib/python3.12/site-packages/tf_keras/src/engine/training.py\", line 588, in __call__\n",
      "\n",
      "  File \"/home/alex/.local/lib/python3.12/site-packages/tf_keras/src/utils/traceback_utils.py\", line 65, in error_handler\n",
      "\n",
      "  File \"/home/alex/.local/lib/python3.12/site-packages/tf_keras/src/engine/base_layer.py\", line 1142, in __call__\n",
      "\n",
      "  File \"/home/alex/.local/lib/python3.12/site-packages/tf_keras/src/utils/traceback_utils.py\", line 96, in error_handler\n",
      "\n",
      "  File \"/home/alex/.local/lib/python3.12/site-packages/tf_keras/src/engine/functional.py\", line 514, in call\n",
      "\n",
      "  File \"/home/alex/.local/lib/python3.12/site-packages/tf_keras/src/engine/functional.py\", line 671, in _run_internal_graph\n",
      "\n",
      "  File \"/home/alex/.local/lib/python3.12/site-packages/tf_keras/src/utils/traceback_utils.py\", line 65, in error_handler\n",
      "\n",
      "  File \"/home/alex/.local/lib/python3.12/site-packages/tf_keras/src/engine/base_layer.py\", line 1142, in __call__\n",
      "\n",
      "  File \"/home/alex/.local/lib/python3.12/site-packages/tf_keras/src/utils/traceback_utils.py\", line 96, in error_handler\n",
      "\n",
      "  File \"/home/alex/.local/lib/python3.12/site-packages/tf_keras/src/layers/normalization/batch_normalization.py\", line 597, in call\n",
      "\n",
      "  File \"/home/alex/.local/lib/python3.12/site-packages/tf_keras/src/layers/normalization/batch_normalization.py\", line 990, in _fused_batch_norm\n",
      "\n",
      "  File \"/home/alex/.local/lib/python3.12/site-packages/tf_keras/src/utils/control_flow_util.py\", line 108, in smart_cond\n",
      "\n",
      "  File \"/home/alex/.local/lib/python3.12/site-packages/tf_keras/src/layers/normalization/batch_normalization.py\", line 979, in _fused_batch_norm_inference\n",
      "\n",
      "No DNN support for stream\n",
      "\t [[{{node model/bn_data/FusedBatchNormV3}}]] [Op:__inference_function_8077]\n",
      "Erreur lors du traitement de data/24_10_09 Soir√©e oeno/IMG_2737.JPG: Graph execution error:\n",
      "\n",
      "Detected at node model/bn_data/FusedBatchNormV3 defined at (most recent call last):\n",
      "  File \"<frozen runpy>\", line 198, in _run_module_as_main\n",
      "\n",
      "  File \"<frozen runpy>\", line 88, in _run_code\n",
      "\n",
      "  File \"/home/alex/.local/lib/python3.12/site-packages/ipykernel_launcher.py\", line 18, in <module>\n",
      "\n",
      "  File \"/home/alex/.local/lib/python3.12/site-packages/traitlets/config/application.py\", line 1075, in launch_instance\n",
      "\n",
      "  File \"/home/alex/.local/lib/python3.12/site-packages/ipykernel/kernelapp.py\", line 739, in start\n",
      "\n",
      "  File \"/home/alex/.local/lib/python3.12/site-packages/tornado/platform/asyncio.py\", line 205, in start\n",
      "\n",
      "  File \"/usr/lib/python3.12/asyncio/base_events.py\", line 641, in run_forever\n",
      "\n",
      "  File \"/usr/lib/python3.12/asyncio/base_events.py\", line 1987, in _run_once\n",
      "\n",
      "  File \"/usr/lib/python3.12/asyncio/events.py\", line 88, in _run\n",
      "\n",
      "  File \"/home/alex/.local/lib/python3.12/site-packages/ipykernel/kernelbase.py\", line 545, in dispatch_queue\n",
      "\n",
      "  File \"/home/alex/.local/lib/python3.12/site-packages/ipykernel/kernelbase.py\", line 534, in process_one\n",
      "\n",
      "  File \"/home/alex/.local/lib/python3.12/site-packages/ipykernel/kernelbase.py\", line 437, in dispatch_shell\n",
      "\n",
      "  File \"/home/alex/.local/lib/python3.12/site-packages/ipykernel/ipkernel.py\", line 362, in execute_request\n",
      "\n",
      "  File \"/home/alex/.local/lib/python3.12/site-packages/ipykernel/kernelbase.py\", line 778, in execute_request\n",
      "\n",
      "  File \"/home/alex/.local/lib/python3.12/site-packages/ipykernel/ipkernel.py\", line 449, in do_execute\n",
      "\n",
      "  File \"/home/alex/.local/lib/python3.12/site-packages/ipykernel/zmqshell.py\", line 549, in run_cell\n",
      "\n",
      "  File \"/home/alex/.local/lib/python3.12/site-packages/IPython/core/interactiveshell.py\", line 3009, in run_cell\n",
      "\n",
      "  File \"/home/alex/.local/lib/python3.12/site-packages/IPython/core/interactiveshell.py\", line 3064, in _run_cell\n",
      "\n",
      "  File \"/home/alex/.local/lib/python3.12/site-packages/IPython/core/async_helpers.py\", line 129, in _pseudo_sync_runner\n",
      "\n",
      "  File \"/home/alex/.local/lib/python3.12/site-packages/IPython/core/interactiveshell.py\", line 3269, in run_cell_async\n",
      "\n",
      "  File \"/home/alex/.local/lib/python3.12/site-packages/IPython/core/interactiveshell.py\", line 3448, in run_ast_nodes\n",
      "\n",
      "  File \"/home/alex/.local/lib/python3.12/site-packages/IPython/core/interactiveshell.py\", line 3508, in run_code\n",
      "\n",
      "  File \"/tmp/ipykernel_82932/3687957463.py\", line 13, in <module>\n",
      "\n",
      "  File \"/tmp/ipykernel_82932/2126864146.py\", line 4, in extract_faces\n",
      "\n",
      "  File \"/home/alex/.local/lib/python3.12/site-packages/deepface/DeepFace.py\", line 549, in extract_faces\n",
      "\n",
      "  File \"/home/alex/.local/lib/python3.12/site-packages/deepface/modules/detection.py\", line 95, in extract_faces\n",
      "\n",
      "  File \"/home/alex/.local/lib/python3.12/site-packages/deepface/modules/detection.py\", line 234, in detect_faces\n",
      "\n",
      "  File \"/home/alex/.local/lib/python3.12/site-packages/deepface/models/face_detection/RetinaFace.py\", line 23, in detect_faces\n",
      "\n",
      "  File \"/home/alex/.local/lib/python3.12/site-packages/retinaface/RetinaFace.py\", line 123, in detect_faces\n",
      "\n",
      "  File \"/home/alex/.local/lib/python3.12/site-packages/tf_keras/src/engine/training.py\", line 553, in error_handler\n",
      "\n",
      "  File \"/home/alex/.local/lib/python3.12/site-packages/tf_keras/src/engine/training.py\", line 558, in error_handler\n",
      "\n",
      "  File \"/home/alex/.local/lib/python3.12/site-packages/tf_keras/src/engine/training.py\", line 588, in __call__\n",
      "\n",
      "  File \"/home/alex/.local/lib/python3.12/site-packages/tf_keras/src/utils/traceback_utils.py\", line 65, in error_handler\n",
      "\n",
      "  File \"/home/alex/.local/lib/python3.12/site-packages/tf_keras/src/engine/base_layer.py\", line 1142, in __call__\n",
      "\n",
      "  File \"/home/alex/.local/lib/python3.12/site-packages/tf_keras/src/utils/traceback_utils.py\", line 96, in error_handler\n",
      "\n",
      "  File \"/home/alex/.local/lib/python3.12/site-packages/tf_keras/src/engine/functional.py\", line 514, in call\n",
      "\n",
      "  File \"/home/alex/.local/lib/python3.12/site-packages/tf_keras/src/engine/functional.py\", line 671, in _run_internal_graph\n",
      "\n",
      "  File \"/home/alex/.local/lib/python3.12/site-packages/tf_keras/src/utils/traceback_utils.py\", line 65, in error_handler\n",
      "\n",
      "  File \"/home/alex/.local/lib/python3.12/site-packages/tf_keras/src/engine/base_layer.py\", line 1142, in __call__\n",
      "\n",
      "  File \"/home/alex/.local/lib/python3.12/site-packages/tf_keras/src/utils/traceback_utils.py\", line 96, in error_handler\n",
      "\n",
      "  File \"/home/alex/.local/lib/python3.12/site-packages/tf_keras/src/layers/normalization/batch_normalization.py\", line 597, in call\n",
      "\n",
      "  File \"/home/alex/.local/lib/python3.12/site-packages/tf_keras/src/layers/normalization/batch_normalization.py\", line 990, in _fused_batch_norm\n",
      "\n",
      "  File \"/home/alex/.local/lib/python3.12/site-packages/tf_keras/src/utils/control_flow_util.py\", line 108, in smart_cond\n",
      "\n",
      "  File \"/home/alex/.local/lib/python3.12/site-packages/tf_keras/src/layers/normalization/batch_normalization.py\", line 979, in _fused_batch_norm_inference\n",
      "\n",
      "No DNN support for stream\n",
      "\t [[{{node model/bn_data/FusedBatchNormV3}}]] [Op:__inference_function_8077]\n"
     ]
    }
   ],
   "source": [
    "# Parcourir le dossier source et traiter les images\n",
    "for root, dirs, files in os.walk(source_dir):\n",
    "    relative_path = os.path.relpath(root, source_dir)\n",
    "\n",
    "    # Cr√©ation du dossier de sauvegarde des faces\n",
    "    output_dir = os.path.join(dest_dir, relative_path)\n",
    "    os.makedirs(output_dir, exist_ok=True)\n",
    "    \n",
    "    for file in files:\n",
    "        if file.lower().endswith('.jpg'):\n",
    "            file_path = os.path.join(root, file)\n",
    "            img_resize = resize_image(file_path, 10)  # Redimensionne l'image\n",
    "            extract_faces(img_resize, file_path, output_dir, align=True)  # Extrait les visages\n",
    "\n",
    "print(\"Traitement termin√©. Les visages sont sauvegard√©s dans :\", dest_dir)\n"
   ]
  }
 ],
 "metadata": {
  "kernelspec": {
   "display_name": "Python 3",
   "language": "python",
   "name": "python3"
  },
  "language_info": {
   "codemirror_mode": {
    "name": "ipython",
    "version": 3
   },
   "file_extension": ".py",
   "mimetype": "text/x-python",
   "name": "python",
   "nbconvert_exporter": "python",
   "pygments_lexer": "ipython3",
   "version": "3.12.3"
  }
 },
 "nbformat": 4,
 "nbformat_minor": 2
}
